Workbook

Sheet Start Here
B2: Debt Payoff Planner
B3: Snowball & Avalanche calculator · Tidy Money Sheets
B5: How to use it
B6: 1 | C6: Open the My Debts tab. Replace the 4 example debts with yours (name, balance, APR, minimum payment). Up to 10 debts.
B7: 2 | C7: Pick your method: Snowball (smallest balance first, quick wins) or Avalanche (highest interest first, saves the most money).
B8: 3 | C8: Enter how much EXTRA you can pay each month on top of your minimums, and the month you start.
B9: 4 | C9: Open the Dashboard: your debt-free date, total interest, money saved vs. paying minimums only, and the exact payoff order.
B10: 5 | C10: The Schedule tab shows every payment, month by month, for every debt. Follow it and watch the balance chart fall.
B12: Legend
C13: Yellow cells = your inputs. Everything else calculates automatically, so don't type over it.
B15: Snowball vs. Avalanche
C16: • Snowball: pay off the smallest balance first. You clear whole debts sooner, which keeps you motivated.
C17: • Avalanche: pay off the highest APR first. Mathematically, it costs you the least interest.
C18: • Not sure? Switch the method on the My Debts tab and compare the 'Total interest' on the Dashboard. It updates instantly.
B20: Google Sheets: File → Make a copy. Excel / Numbers: open the file directly.
B21: This planner is an educational tool, not financial advice. Real lender interest may be calculated slightly differently.

Sheet My Debts
B2: My Debts
B3: Fill in the yellow cells. The rest updates by itself.
B5: Payoff method | C5: Snowball | E5: Total monthly payment
B6: Extra payment per month | C6: 200 | E6: =SUM(E10:E19)+C6 -> 730
B7: First payment month | C7: 46327 | E7: (all minimums + extra)
B9: Debt name | C9: Balance | D9: APR | E9: Minimum payment | F9: Priority | G9: Paid off
B10: Visa credit card | C10: 6850 | D10: 0.2499 | E10: 175 | F10: =IF(OR(C10="",C10<=0),"",MATCH(1,Sorted!$C$2:$C$11,0)) -> 4 | G10: =IF(F10="","",INDEX(Dashboard!$G$17:$G$26,F10)) -> 46997
B11: Car loan | C11: 4300 | D11: 0.074 | E11: 240 | F11: =IF(OR(C11="",C11<=0),"",MATCH(2,Sorted!$C$2:$C$11,0)) -> 3 | G11: =IF(F11="","",INDEX(Dashboard!$G$17:$G$26,F11)) -> 46692
B12: Store card | C12: 1450 | D12: 0.2999 | E12: 55 | F12: =IF(OR(C12="",C12<=0),"",MATCH(3,Sorted!$C$2:$C$11,0)) -> 2 | G12: =IF(F12="","",INDEX(Dashboard!$G$17:$G$26,F12)) -> 46569
B13: Personal loan | C13: 900 | D13: 0.115 | E13: 60 | F13: =IF(OR(C13="",C13<=0),"",MATCH(4,Sorted!$C$2:$C$11,0)) -> 1 | G13: =IF(F13="","",INDEX(Dashboard!$G$17:$G$26,F13)) -> 46419
F14: =IF(OR(C14="",C14<=0),"",MATCH(5,Sorted!$C$2:$C$11,0)) | G14: =IF(F14="","",INDEX(Dashboard!$G$17:$G$26,F14))
F15: =IF(OR(C15="",C15<=0),"",MATCH(6,Sorted!$C$2:$C$11,0)) | G15: =IF(F15="","",INDEX(Dashboard!$G$17:$G$26,F15))
F16: =IF(OR(C16="",C16<=0),"",MATCH(7,Sorted!$C$2:$C$11,0)) | G16: =IF(F16="","",INDEX(Dashboard!$G$17:$G$26,F16))
F17: =IF(OR(C17="",C17<=0),"",MATCH(8,Sorted!$C$2:$C$11,0)) | G17: =IF(F17="","",INDEX(Dashboard!$G$17:$G$26,F17))
F18: =IF(OR(C18="",C18<=0),"",MATCH(9,Sorted!$C$2:$C$11,0)) | G18: =IF(F18="","",INDEX(Dashboard!$G$17:$G$26,F18))
F19: =IF(OR(C19="",C19<=0),"",MATCH(10,Sorted!$C$2:$C$11,0)) | G19: =IF(F19="","",INDEX(Dashboard!$G$17:$G$26,F19))
B21: Tip: enter APR as a percentage (e.g. 22.99%). Leave unused rows empty.

Sheet Dashboard
B2: Your Debt-Free Dashboard
B3: ="Method: "&'My Debts'!$C$5&" · Paying "&TEXT('My Debts'!$E$6,"$#,##0")&" per month" -> Method: Snowball · Paying $730 per month
B5: Total debt today | D5: Debt-free date | F5: Interest saved
B6: =SUM('My Debts'!$C$10:$C$19) -> 13500 | D6: =IF(ISNUMBER(D10),EDATE('My Debts'!$C$7,D10-1),"Not within 20 yrs") -> 46997 | F6: =IF(ISNUMBER(E13),E13,"") -> 5799.08
D9: Your plan | E9: Minimums only
C10: Months to debt-free | D10: =IF(SUM('My Debts'!$C$10:$C$19)<=0,"",IF(COUNTIF(Schedule!$E$4:$E$243,">0.01")>=240,"20+ yrs",COUNTIF(Schedule!$E$4:$E$243,">0.01")+1)) -> 23 | E10: =IF(SUM('My Debts'!$C$10:$C$19)<=0,"",IF(COUNTIF(MinOnly!$E$4:$E$243,">0.01")>=240,"20+ yrs",COUNTIF(MinOnly!$E$4:$E$243,">0.01")+1)) -> 82
C11: Total interest paid | D11: =IF(SUM('My Debts'!$C$10:$C$19)<=0,0,SUM(Schedule!$D$4:$D$243)+Schedule!$E$243-SUM('My Debts'!$C$10:$C$19)) -> 2978.42 | E11: =IF(SUM('My Debts'!$C$10:$C$19)<=0,0,SUM(MinOnly!$D$4:$D$243)+MinOnly!$E$243-SUM('My Debts'!$C$10:$C$19)) -> 8777.5
C12: Total you'll pay | D12: =SUM('My Debts'!$C$10:$C$19)+D11 -> 16478.42 | E12: =SUM('My Debts'!$C$10:$C$19)+E11 -> 22277.5
C13: You save | D13: =IF(AND(ISNUMBER(D10),ISNUMBER(E10)),(E10-D10)&" months sooner",IF(ISNUMBER(D10),"Free 20+ yrs sooner","")) -> 59 months sooner | E13: =E11-D11 -> 5799.08
B15: Payoff order
B16: # | C16: Debt | D16: Balance | E16: APR | F16: Months | G16: Paid off
B17: =IF(Sorted!$D$2="","",1) -> 1 | C17: =Sorted!$D$2 -> Personal loan | D17: =IF(C17="","",Sorted!$E$2) -> 900 | E17: =IF(C17="","",Sorted!$F$2) -> 0.115 | F17: =IF(C17="","",IF(COUNTIF(Schedule!$I$4:$I$243,">0.01")>=240,"20+ yrs",COUNTIF(Schedule!$I$4:$I$243,">0.01")+1)) -> 4 | G17: =IF(ISNUMBER(F17),EDATE('My Debts'!$C$7,F17-1),IF(C17="","","—")) -> 46419
B18: =IF(Sorted!$D$3="","",2) -> 2 | C18: =Sorted!$D$3 -> Store card | D18: =IF(C18="","",Sorted!$E$3) -> 1450 | E18: =IF(C18="","",Sorted!$F$3) -> 0.2999 | F18: =IF(C18="","",IF(COUNTIF(Schedule!$M$4:$M$243,">0.01")>=240,"20+ yrs",COUNTIF(Schedule!$M$4:$M$243,">0.01")+1)) -> 9 | G18: =IF(ISNUMBER(F18),EDATE('My Debts'!$C$7,F18-1),IF(C18="","","—")) -> 46569
B19: =IF(Sorted!$D$4="","",3) -> 3 | C19: =Sorted!$D$4 -> Car loan | D19: =IF(C19="","",Sorted!$E$4) -> 4300 | E19: =IF(C19="","",Sorted!$F$4) -> 0.074 | F19: =IF(C19="","",IF(COUNTIF(Schedule!$Q$4:$Q$243,">0.01")>=240,"20+ yrs",COUNTIF(Schedule!$Q$4:$Q$243,">0.01")+1)) -> 13 | G19: =IF(ISNUMBER(F19),EDATE('My Debts'!$C$7,F19-1),IF(C19="","","—")) -> 46692
B20: =IF(Sorted!$D$5="","",4) -> 4 | C20: =Sorted!$D$5 -> Visa credit card | D20: =IF(C20="","",Sorted!$E$5) -> 6850 | E20: =IF(C20="","",Sorted!$F$5) -> 0.2499 | F20: =IF(C20="","",IF(COUNTIF(Schedule!$U$4:$U$243,">0.01")>=240,"20+ yrs",COUNTIF(Schedule!$U$4:$U$243,">0.01")+1)) -> 23 | G20: =IF(ISNUMBER(F20),EDATE('My Debts'!$C$7,F20-1),IF(C20="","","—")) -> 46997
B21: =IF(Sorted!$D$6="","",5) | C21: =Sorted!$D$6 | D21: =IF(C21="","",Sorted!$E$6) | E21: =IF(C21="","",Sorted!$F$6) | F21: =IF(C21="","",IF(COUNTIF(Schedule!$Y$4:$Y$243,">0.01")>=240,"20+ yrs",COUNTIF(Schedule!$Y$4:$Y$243,">0.01")+1)) | G21: =IF(ISNUMBER(F21),EDATE('My Debts'!$C$7,F21-1),IF(C21="","","—"))
B22: =IF(Sorted!$D$7="","",6) | C22: =Sorted!$D$7 | D22: =IF(C22="","",Sorted!$E$7) | E22: =IF(C22="","",Sorted!$F$7) | F22: =IF(C22="","",IF(COUNTIF(Schedule!$AC$4:$AC$243,">0.01")>=240,"20+ yrs",COUNTIF(Schedule!$AC$4:$AC$243,">0.01")+1)) | G22: =IF(ISNUMBER(F22),EDATE('My Debts'!$C$7,F22-1),IF(C22="","","—"))
B23: =IF(Sorted!$D$8="","",7) | C23: =Sorted!$D$8 | D23: =IF(C23="","",Sorted!$E$8) | E23: =IF(C23="","",Sorted!$F$8) | F23: =IF(C23="","",IF(COUNTIF(Schedule!$AG$4:$AG$243,">0.01")>=240,"20+ yrs",COUNTIF(Schedule!$AG$4:$AG$243,">0.01")+1)) | G23: =IF(ISNUMBER(F23),EDATE('My Debts'!$C$7,F23-1),IF(C23="","","—"))
B24: =IF(Sorted!$D$9="","",8) | C24: =Sorted!$D$9 | D24: =IF(C24="","",Sorted!$E$9) | E24: =IF(C24="","",Sorted!$F$9) | F24: =IF(C24="","",IF(COUNTIF(Schedule!$AK$4:$AK$243,">0.01")>=240,"20+ yrs",COUNTIF(Schedule!$AK$4:$AK$243,">0.01")+1)) | G24: =IF(ISNUMBER(F24),EDATE('My Debts'!$C$7,F24-1),IF(C24="","","—"))
B25: =IF(Sorted!$D$10="","",9) | C25: =Sorted!$D$10 | D25: =IF(C25="","",Sorted!$E$10) | E25: =IF(C25="","",Sorted!$F$10) | F25: =IF(C25="","",IF(COUNTIF(Schedule!$AO$4:$AO$243,">0.01")>=240,"20+ yrs",COUNTIF(Schedule!$AO$4:$AO$243,">0.01")+1)) | G25: =IF(ISNUMBER(F25),EDATE('My Debts'!$C$7,F25-1),IF(C25="","","—"))
B26: =IF(Sorted!$D$11="","",10) | C26: =Sorted!$D$11 | D26: =IF(C26="","",Sorted!$E$11) | E26: =IF(C26="","",Sorted!$F$11) | F26: =IF(C26="","",IF(COUNTIF(Schedule!$AS$4:$AS$243,">0.01")>=240,"20+ yrs",COUNTIF(Schedule!$AS$4:$AS$243,">0.01")+1)) | G26: =IF(ISNUMBER(F26),EDATE('My Debts'!$C$7,F26-1),IF(C26="","","—"))

Sheet Sorted
A1: Sort key (input row order) | B1: Sorted key | C1: Input row # | D1: Debt | E1: Balance | F1: APR | G1: Min payment | H1: Monthly rate
A2: =IF(OR('My Debts'!C10="",'My Debts'!C10<=0),1000000000000+1,IF('My Debts'!$C$5="Avalanche",-N('My Debts'!D10)*1000+1/1000,'My Debts'!C10+1/1000000)) -> 6850 | B2: =SMALL($A$2:$A$11,1) -> 900 | C2: =MATCH(B2,$A$2:$A$11,0) -> 4 | D2: =IF(B2<1000000000000,INDEX('My Debts'!$B$10:$B$19,C2),"") -> Personal loan | E2: =IF(B2<1000000000000,INDEX('My Debts'!$C$10:$C$19,C2),0) -> 900 | F2: =IF(B2<1000000000000,N(INDEX('My Debts'!$D$10:$D$19,C2)),0) -> 0.115 | G2: =IF(B2<1000000000000,N(INDEX('My Debts'!$E$10:$E$19,C2)),0) -> 60 | H2: =F2/12 -> 0.0095833333
A3: =IF(OR('My Debts'!C11="",'My Debts'!C11<=0),1000000000000+2,IF('My Debts'!$C$5="Avalanche",-N('My Debts'!D11)*1000+2/1000,'My Debts'!C11+2/1000000)) -> 4300 | B3: =SMALL($A$2:$A$11,2) -> 1450 | C3: =MATCH(B3,$A$2:$A$11,0) -> 3 | D3: =IF(B3<1000000000000,INDEX('My Debts'!$B$10:$B$19,C3),"") -> Store card | E3: =IF(B3<1000000000000,INDEX('My Debts'!$C$10:$C$19,C3),0) -> 1450 | F3: =IF(B3<1000000000000,N(INDEX('My Debts'!$D$10:$D$19,C3)),0) -> 0.2999 | G3: =IF(B3<1000000000000,N(INDEX('My Debts'!$E$10:$E$19,C3)),0) -> 55 | H3: =F3/12 -> 0.024991667
A4: =IF(OR('My Debts'!C12="",'My Debts'!C12<=0),1000000000000+3,IF('My Debts'!$C$5="Avalanche",-N('My Debts'!D12)*1000+3/1000,'My Debts'!C12+3/1000000)) -> 1450 | B4: =SMALL($A$2:$A$11,3) -> 4300 | C4: =MATCH(B4,$A$2:$A$11,0) -> 2 | D4: =IF(B4<1000000000000,INDEX('My Debts'!$B$10:$B$19,C4),"") -> Car loan | E4: =IF(B4<1000000000000,INDEX('My Debts'!$C$10:$C$19,C4),0) -> 4300 | F4: =IF(B4<1000000000000,N(INDEX('My Debts'!$D$10:$D$19,C4)),0) -> 0.074 | G4: =IF(B4<1000000000000,N(INDEX('My Debts'!$E$10:$E$19,C4)),0) -> 240 | H4: =F4/12 -> 0.0061666667
A5: =IF(OR('My Debts'!C13="",'My Debts'!C13<=0),1000000000000+4,IF('My Debts'!$C$5="Avalanche",-N('My Debts'!D13)*1000+4/1000,'My Debts'!C13+4/1000000)) -> 900 | B5: =SMALL($A$2:$A$11,4) -> 6850 | C5: =MATCH(B5,$A$2:$A$11,0) -> 1 | D5: =IF(B5<1000000000000,INDEX('My Debts'!$B$10:$B$19,C5),"") -> Visa credit card | E5: =IF(B5<1000000000000,INDEX('My Debts'!$C$10:$C$19,C5),0) -> 6850 | F5: =IF(B5<1000000000000,N(INDEX('My Debts'!$D$10:$D$19,C5)),0) -> 0.2499 | G5: =IF(B5<1000000000000,N(INDEX('My Debts'!$E$10:$E$19,C5)),0) -> 175 | H5: =F5/12 -> 0.020825
A6: =IF(OR('My Debts'!C14="",'My Debts'!C14<=0),1000000000000+5,IF('My Debts'!$C$5="Avalanche",-N('My Debts'!D14)*1000+5/1000,'My Debts'!C14+5/1000000)) -> 1000000000005 | B6: =SMALL($A$2:$A$11,5) -> 1000000000005 | C6: =MATCH(B6,$A$2:$A$11,0) -> 5 | D6: =IF(B6<1000000000000,INDEX('My Debts'!$B$10:$B$19,C6),"") | E6: =IF(B6<1000000000000,INDEX('My Debts'!$C$10:$C$19,C6),0) -> 0 | F6: =IF(B6<1000000000000,N(INDEX('My Debts'!$D$10:$D$19,C6)),0) -> 0 | G6: =IF(B6<1000000000000,N(INDEX('My Debts'!$E$10:$E$19,C6)),0) -> 0 | H6: =F6/12 -> 0
A7: =IF(OR('My Debts'!C15="",'My Debts'!C15<=0),1000000000000+6,IF('My Debts'!$C$5="Avalanche",-N('My Debts'!D15)*1000+6/1000,'My Debts'!C15+6/1000000)) -> 1000000000006 | B7: =SMALL($A$2:$A$11,6) -> 1000000000006 | C7: =MATCH(B7,$A$2:$A$11,0) -> 6 | D7: =IF(B7<1000000000000,INDEX('My Debts'!$B$10:$B$19,C7),"") | E7: =IF(B7<1000000000000,INDEX('My Debts'!$C$10:$C$19,C7),0) -> 0 | F7: =IF(B7<1000000000000,N(INDEX('My Debts'!$D$10:$D$19,C7)),0) -> 0 | G7: =IF(B7<1000000000000,N(INDEX('My Debts'!$E$10:$E$19,C7)),0) -> 0 | H7: =F7/12 -> 0
A8: =IF(OR('My Debts'!C16="",'My Debts'!C16<=0),1000000000000+7,IF('My Debts'!$C$5="Avalanche",-N('My Debts'!D16)*1000+7/1000,'My Debts'!C16+7/1000000)) -> 1000000000007 | B8: =SMALL($A$2:$A$11,7) -> 1000000000007 | C8: =MATCH(B8,$A$2:$A$11,0) -> 7 | D8: =IF(B8<1000000000000,INDEX('My Debts'!$B$10:$B$19,C8),"") | E8: =IF(B8<1000000000000,INDEX('My Debts'!$C$10:$C$19,C8),0) -> 0 | F8: =IF(B8<1000000000000,N(INDEX('My Debts'!$D$10:$D$19,C8)),0) -> 0 | G8: =IF(B8<1000000000000,N(INDEX('My Debts'!$E$10:$E$19,C8)),0) -> 0 | H8: =F8/12 -> 0
A9: =IF(OR('My Debts'!C17="",'My Debts'!C17<=0),1000000000000+8,IF('My Debts'!$C$5="Avalanche",-N('My Debts'!D17)*1000+8/1000,'My Debts'!C17+8/1000000)) -> 1000000000008 | B9: =SMALL($A$2:$A$11,8) -> 1000000000008 | C9: =MATCH(B9,$A$2:$A$11,0) -> 8 | D9: =IF(B9<1000000000000,INDEX('My Debts'!$B$10:$B$19,C9),"") | E9: =IF(B9<1000000000000,INDEX('My Debts'!$C$10:$C$19,C9),0) -> 0 | F9: =IF(B9<1000000000000,N(INDEX('My Debts'!$D$10:$D$19,C9)),0) -> 0 | G9: =IF(B9<1000000000000,N(INDEX('My Debts'!$E$10:$E$19,C9)),0) -> 0 | H9: =F9/12 -> 0
A10: =IF(OR('My Debts'!C18="",'My Debts'!C18<=0),1000000000000+9,IF('My Debts'!$C$5="Avalanche",-N('My Debts'!D18)*1000+9/1000,'My Debts'!C18+9/1000000)) -> 1000000000009 | B10: =SMALL($A$2:$A$11,9) -> 1000000000009 | C10: =MATCH(B10,$A$2:$A$11,0) -> 9 | D10: =IF(B10<1000000000000,INDEX('My Debts'!$B$10:$B$19,C10),"") | E10: =IF(B10<1000000000000,INDEX('My Debts'!$C$10:$C$19,C10),0) -> 0 | F10: =IF(B10<1000000000000,N(INDEX('My Debts'!$D$10:$D$19,C10)),0) -> 0 | G10: =IF(B10<1000000000000,N(INDEX('My Debts'!$E$10:$E$19,C10)),0) -> 0 | H10: =F10/12 -> 0
A11: =IF(OR('My Debts'!C19="",'My Debts'!C19<=0),1000000000000+10,IF('My Debts'!$C$5="Avalanche",-N('My Debts'!D19)*1000+10/1000,'My Debts'!C19+10/1000000)) -> 1000000000010 | B11: =SMALL($A$2:$A$11,10) -> 1000000000010 | C11: =MATCH(B11,$A$2:$A$11,0) -> 10 | D11: =IF(B11<1000000000000,INDEX('My Debts'!$B$10:$B$19,C11),"") | E11: =IF(B11<1000000000000,INDEX('My Debts'!$C$10:$C$19,C11),0) -> 0 | F11: =IF(B11<1000000000000,N(INDEX('My Debts'!$D$10:$D$19,C11)),0) -> 0 | G11: =IF(B11<1000000000000,N(INDEX('My Debts'!$E$10:$E$19,C11)),0) -> 0 | H11: =F11/12 -> 0

Sheet Schedule
A1: Payment schedule: your plan
F2: =IF(Sorted!$D$2="","",Sorted!$D$2) -> Personal loan | J2: =IF(Sorted!$D$3="","",Sorted!$D$3) -> Store card | N2: =IF(Sorted!$D$4="","",Sorted!$D$4) -> Car loan | R2: =IF(Sorted!$D$5="","",Sorted!$D$5) -> Visa credit card | V2: =IF(Sorted!$D$6="","",Sorted!$D$6) | Z2: =IF(Sorted!$D$7="","",Sorted!$D$7) | AD2: =IF(Sorted!$D$8="","",Sorted!$D$8) | AH2: =IF(Sorted!$D$9="","",Sorted!$D$9) | AL2: =IF(Sorted!$D$10="","",Sorted!$D$10) | AP2: =IF(Sorted!$D$11="","",Sorted!$D$11)
A3: Month | B3: Date | C3: Extra to allocate | D3: Total paid | E3: Total balance | F3: After interest | G3: Minimum | H3: Extra | I3: Balance | J3: After interest | K3: Minimum | L3: Extra | M3: Balance | N3: After interest | O3: Minimum | P3: Extra | Q3: Balance | R3: After interest | S3: Minimum | T3: Extra | U3: Balance | V3: After interest | W3: Minimum | X3: Extra | Y3: Balance | Z3: After interest | AA3: Minimum | AB3: Extra | AC3: Balance | AD3: After interest | AE3: Minimum | AF3: Extra | AG3: Balance | AH3: After interest | AI3: Minimum | AJ3: Extra | AK3: Balance | AL3: After interest | AM3: Minimum | AN3: Extra | AO3: Balance | AP3: After interest | AQ3: Minimum | AR3: Extra | AS3: Balance
A4: 1 | B4: =EDATE('My Debts'!$C$7,A4-1) -> 46327 | C4: =MAX(0,'My Debts'!$E$6-(G4+K4+O4+S4+W4+AA4+AE4+AI4+AM4+AQ4)) -> 200 | D4: =(F4+J4+N4+R4+V4+Z4+AD4+AH4+AL4+AP4)-(I4+M4+Q4+U4+Y4+AC4+AG4+AK4+AO4+AS4) -> 730 | E4: =I4+M4+Q4+U4+Y4+AC4+AG4+AK4+AO4+AS4 -> 12984.04 | F4: =ROUND(Sorted!$E$2*(1+Sorted!$H$2),2) -> 908.63 | G4: =MIN(F4,Sorted!$G$2) -> 60 | H4: =MAX(0,MIN(F4-G4,$C4-(0))) -> 200 | I4: =ROUND(F4-G4-H4,2) -> 648.63 | J4: =ROUND(Sorted!$E$3*(1+Sorted!$H$3),2) -> 1486.24 | K4: =MIN(J4,Sorted!$G$3) -> 55 | L4: =MAX(0,MIN(J4-K4,$C4-(H4))) -> 0 | M4: =ROUND(J4-K4-L4,2) -> 1431.24 | N4: =ROUND(Sorted!$E$4*(1+Sorted!$H$4),2) -> 4326.52 | O4: =MIN(N4,Sorted!$G$4) -> 240 | P4: =MAX(0,MIN(N4-O4,$C4-(H4+L4))) -> 0 | Q4: =ROUND(N4-O4-P4,2) -> 4086.52 | R4: =ROUND(Sorted!$E$5*(1+Sorted!$H$5),2) -> 6992.65 | S4: =MIN(R4,Sorted!$G$5) -> 175 | T4: =MAX(0,MIN(R4-S4,$C4-(H4+L4+P4))) -> 0 | U4: =ROUND(R4-S4-T4,2) -> 6817.65 | V4: =ROUND(Sorted!$E$6*(1+Sorted!$H$6),2) -> 0 | W4: =MIN(V4,Sorted!$G$6) -> 0 | X4: =MAX(0,MIN(V4-W4,$C4-(H4+L4+P4+T4))) -> 0 | Y4: =ROUND(V4-W4-X4,2) -> 0 | Z4: =ROUND(Sorted!$E$7*(1+Sorted!$H$7),2) -> 0 | AA4: =MIN(Z4,Sorted!$G$7) -> 0 | AB4: =MAX(0,MIN(Z4-AA4,$C4-(H4+L4+P4+T4+X4))) -> 0 | AC4: =ROUND(Z4-AA4-AB4,2) -> 0 | AD4: =ROUND(Sorted!$E$8*(1+Sorted!$H$8),2) -> 0 | AE4: =MIN(AD4,Sorted!$G$8) -> 0 | AF4: =MAX(0,MIN(AD4-AE4,$C4-(H4+L4+P4+T4+X4+AB4))) -> 0 | AG4: =ROUND(AD4-AE4-AF4,2) -> 0 | AH4: =ROUND(Sorted!$E$9*(1+Sorted!$H$9),2) -> 0 | AI4: =MIN(AH4,Sorted!$G$9) -> 0 | AJ4: =MAX(0,MIN(AH4-AI4,$C4-(H4+L4+P4+T4+X4+AB4+AF4))) -> 0 | AK4: =ROUND(AH4-AI4-AJ4,2) -> 0 | AL4: =ROUND(Sorted!$E$10*(1+Sorted!$H$10),2) -> 0 | AM4: =MIN(AL4,Sorted!$G$10) -> 0 | AN4: =MAX(0,MIN(AL4-AM4,$C4-(H4+L4+P4+T4+X4+AB4+AF4+AJ4))) -> 0 | AO4: =ROUND(AL4-AM4-AN4,2) -> 0 | AP4: =ROUND(Sorted!$E$11*(1+Sorted!$H$11),2) -> 0 | AQ4: =MIN(AP4,Sorted!$G$11) -> 0 | AR4: =MAX(0,MIN(AP4-AQ4,$C4-(H4+L4+P4+T4+X4+AB4+AF4+AJ4+AN4))) -> 0 | AS4: =ROUND(AP4-AQ4-AR4,2) -> 0
A5: 2 | B5: =EDATE('My Debts'!$C$7,A5-1) -> 46357 | C5: =MAX(0,'My Debts'!$E$6-(G5+K5+O5+S5+W5+AA5+AE5+AI5+AM5+AQ5)) -> 200 | D5: =(F5+J5+N5+R5+V5+Z5+AD5+AH5+AL5+AP5)-(I5+M5+Q5+U5+Y5+AC5+AG5+AK5+AO5+AS5) -> 730 | E5: =I5+M5+Q5+U5+Y5+AC5+AG5+AK5+AO5+AS5 -> 12463.21 | F5: =ROUND(I4*(1+Sorted!$H$2),2) -> 654.85 | G5: =MIN(F5,Sorted!$G$2) -> 60 | H5: =MAX(0,MIN(F5-G5,$C5-(0))) -> 200 | I5: =ROUND(F5-G5-H5,2) -> 394.85 | J5: =ROUND(M4*(1+Sorted!$H$3),2) -> 1467.01 | K5: =MIN(J5,Sorted!$G$3) -> 55 | L5: =MAX(0,MIN(J5-K5,$C5-(H5))) -> 0 | M5: =ROUND(J5-K5-L5,2) -> 1412.01 | N5: =ROUND(Q4*(1+Sorted!$H$4),2) -> 4111.72 | O5: =MIN(N5,Sorted!$G$4) -> 240 | P5: =MAX(0,MIN(N5-O5,$C5-(H5+L5))) -> 0 | Q5: =ROUND(N5-O5-P5,2) -> 3871.72 | R5: =ROUND(U4*(1+Sorted!$H$5),2) -> 6959.63 | S5: =MIN(R5,Sorted!$G$5) -> 175 | T5: =MAX(0,MIN(R5-S5,$C5-(H5+L5+P5))) -> 0 | U5: =ROUND(R5-S5-T5,2) -> 6784.63 | V5: =ROUND(Y4*(1+Sorted!$H$6),2) -> 0 | W5: =MIN(V5,Sorted!$G$6) -> 0 | X5: =MAX(0,MIN(V5-W5,$C5-(H5+L5+P5+T5))) -> 0 | Y5: =ROUND(V5-W5-X5,2) -> 0 | Z5: =ROUND(AC4*(1+Sorted!$H$7),2) -> 0 | AA5: =MIN(Z5,Sorted!$G$7) -> 0 | AB5: =MAX(0,MIN(Z5-AA5,$C5-(H5+L5+P5+T5+X5))) -> 0 | AC5: =ROUND(Z5-AA5-AB5,2) -> 0 | AD5: =ROUND(AG4*(1+Sorted!$H$8),2) -> 0 | AE5: =MIN(AD5,Sorted!$G$8) -> 0 | AF5: =MAX(0,MIN(AD5-AE5,$C5-(H5+L5+P5+T5+X5+AB5))) -> 0 | AG5: =ROUND(AD5-AE5-AF5,2) -> 0 | AH5: =ROUND(AK4*(1+Sorted!$H$9),2) -> 0 | AI5: =MIN(AH5,Sorted!$G$9) -> 0 | AJ5: =MAX(0,MIN(AH5-AI5,$C5-(H5+L5+P5+T5+X5+AB5+AF5))) -> 0 | AK5: =ROUND(AH5-AI5-AJ5,2) -> 0 | AL5: =ROUND(AO4*(1+Sorted!$H$10),2) -> 0 | AM5: =MIN(AL5,Sorted!$G$10) -> 0 | AN5: =MAX(0,MIN(AL5-AM5,$C5-(H5+L5+P5+T5+X5+AB5+AF5+AJ5))) -> 0 | AO5: =ROUND(AL5-AM5-AN5,2) -> 0 | AP5: =ROUND(AS4*(1+Sorted!$H$11),2) -> 0 | AQ5: =MIN(AP5,Sorted!$G$11) -> 0 | AR5: =MAX(0,MIN(AP5-AQ5,$C5-(H5+L5+P5+T5+X5+AB5+AF5+AJ5+AN5))) -> 0 | AS5: =ROUND(AP5-AQ5-AR5,2) -> 0
A6: 3 | B6: =EDATE('My Debts'!$C$7,A6-1) -> 46388 | C6: =MAX(0,'My Debts'!$E$6-(G6+K6+O6+S6+W6+AA6+AE6+AI6+AM6+AQ6)) -> 200 | D6: =(F6+J6+N6+R6+V6+Z6+AD6+AH6+AL6+AP6)-(I6+M6+Q6+U6+Y6+AC6+AG6+AK6+AO6+AS6) -> 730 | E6: =I6+M6+Q6+U6+Y6+AC6+AG6+AK6+AO6+AS6 -> 11937.45 | F6: =ROUND(I5*(1+Sorted!$H$2),2) -> 398.63 | G6: =MIN(F6,Sorted!$G$2) -> 60 | H6: =MAX(0,MIN(F6-G6,$C6-(0))) -> 200 | I6: =ROUND(F6-G6-H6,2) -> 138.63 | J6: =ROUND(M5*(1+Sorted!$H$3),2) -> 1447.3 | K6: =MIN(J6,Sorted!$G$3) -> 55 | L6: =MAX(0,MIN(J6-K6,$C6-(H6))) -> 0 | M6: =ROUND(J6-K6-L6,2) -> 1392.3 | N6: =ROUND(Q5*(1+Sorted!$H$4),2) -> 3895.6 | O6: =MIN(N6,Sorted!$G$4) -> 240 | P6: =MAX(0,MIN(N6-O6,$C6-(H6+L6))) -> 0 | Q6: =ROUND(N6-O6-P6,2) -> 3655.6 | R6: =ROUND(U5*(1+Sorted!$H$5),2) -> 6925.92 | S6: =MIN(R6,Sorted!$G$5) -> 175 | T6: =MAX(0,MIN(R6-S6,$C6-(H6+L6+P6))) -> 0 | U6: =ROUND(R6-S6-T6,2) -> 6750.92 | V6: =ROUND(Y5*(1+Sorted!$H$6),2) -> 0 | W6: =MIN(V6,Sorted!$G$6) -> 0 | X6: =MAX(0,MIN(V6-W6,$C6-(H6+L6+P6+T6))) -> 0 | Y6: =ROUND(V6-W6-X6,2) -> 0 | Z6: =ROUND(AC5*(1+Sorted!$H$7),2) -> 0 | AA6: =MIN(Z6,Sorted!$G$7) -> 0 | AB6: =MAX(0,MIN(Z6-AA6,$C6-(H6+L6+P6+T6+X6))) -> 0 | AC6: =ROUND(Z6-AA6-AB6,2) -> 0 | AD6: =ROUND(AG5*(1+Sorted!$H$8),2) -> 0 | AE6: =MIN(AD6,Sorted!$G$8) -> 0 | AF6: =MAX(0,MIN(AD6-AE6,$C6-(H6+L6+P6+T6+X6+AB6))) -> 0 | AG6: =ROUND(AD6-AE6-AF6,2) -> 0 | AH6: =ROUND(AK5*(1+Sorted!$H$9),2) -> 0 | AI6: =MIN(AH6,Sorted!$G$9) -> 0 | AJ6: =MAX(0,MIN(AH6-AI6,$C6-(H6+L6+P6+T6+X6+AB6+AF6))) -> 0 | AK6: =ROUND(AH6-AI6-AJ6,2) -> 0 | AL6: =ROUND(AO5*(1+Sorted!$H$10),2) -> 0 | AM6: =MIN(AL6,Sorted!$G$10) -> 0 | AN6: =MAX(0,MIN(AL6-AM6,$C6-(H6+L6+P6+T6+X6+AB6+AF6+AJ6))) -> 0 | AO6: =ROUND(AL6-AM6-AN6,2) -> 0 | AP6: =ROUND(AS5*(1+Sorted!$H$11),2) -> 0 | AQ6: =MIN(AP6,Sorted!$G$11) -> 0 | AR6: =MAX(0,MIN(AP6-AQ6,$C6-(H6+L6+P6+T6+X6+AB6+AF6+AJ6+AN6))) -> 0 | AS6: =ROUND(AP6-AQ6-AR6,2) -> 0
A7: 4 | B7: =EDATE('My Debts'!$C$7,A7-1) -> 46419 | C7: =MAX(0,'My Debts'!$E$6-(G7+K7+O7+S7+W7+AA7+AE7+AI7+AM7+AQ7)) -> 200 | D7: =(F7+J7+N7+R7+V7+Z7+AD7+AH7+AL7+AP7)-(I7+M7+Q7+U7+Y7+AC7+AG7+AK7+AO7+AS7) -> 730 | E7: =I7+M7+Q7+U7+Y7+AC7+AG7+AK7+AO7+AS7 -> 11406.71 | F7: =ROUND(I6*(1+Sorted!$H$2),2) -> 139.96 | G7: =MIN(F7,Sorted!$G$2) -> 60 | H7: =MAX(0,MIN(F7-G7,$C7-(0))) -> 79.96 | I7: =ROUND(F7-G7-H7,2) -> 0 | J7: =ROUND(M6*(1+Sorted!$H$3),2) -> 1427.1 | K7: =MIN(J7,Sorted!$G$3) -> 55 | L7: =MAX(0,MIN(J7-K7,$C7-(H7))) -> 120.04 | M7: =ROUND(J7-K7-L7,2) -> 1252.06 | N7: =ROUND(Q6*(1+Sorted!$H$4),2) -> 3678.14 | O7: =MIN(N7,Sorted!$G$4) -> 240 | P7: =MAX(0,MIN(N7-O7,$C7-(H7+L7))) -> 0 | Q7: =ROUND(N7-O7-P7,2) -> 3438.14 | R7: =ROUND(U6*(1+Sorted!$H$5),2) -> 6891.51 | S7: =MIN(R7,Sorted!$G$5) -> 175 | T7: =MAX(0,MIN(R7-S7,$C7-(H7+L7+P7))) -> 0 | U7: =ROUND(R7-S7-T7,2) -> 6716.51 | V7: =ROUND(Y6*(1+Sorted!$H$6),2) -> 0 | W7: =MIN(V7,Sorted!$G$6) -> 0 | X7: =MAX(0,MIN(V7-W7,$C7-(H7+L7+P7+T7))) -> 0 | Y7: =ROUND(V7-W7-X7,2) -> 0 | Z7: =ROUND(AC6*(1+Sorted!$H$7),2) -> 0 | AA7: =MIN(Z7,Sorted!$G$7) -> 0 | AB7: =MAX(0,MIN(Z7-AA7,$C7-(H7+L7+P7+T7+X7))) -> 0 | AC7: =ROUND(Z7-AA7-AB7,2) -> 0 | AD7: =ROUND(AG6*(1+Sorted!$H$8),2) -> 0 | AE7: =MIN(AD7,Sorted!$G$8) -> 0 | AF7: =MAX(0,MIN(AD7-AE7,$C7-(H7+L7+P7+T7+X7+AB7))) -> 0 | AG7: =ROUND(AD7-AE7-AF7,2) -> 0 | AH7: =ROUND(AK6*(1+Sorted!$H$9),2) -> 0 | AI7: =MIN(AH7,Sorted!$G$9) -> 0 | AJ7: =MAX(0,MIN(AH7-AI7,$C7-(H7+L7+P7+T7+X7+AB7+AF7))) -> 0 | AK7: =ROUND(AH7-AI7-AJ7,2) -> 0 | AL7: =ROUND(AO6*(1+Sorted!$H$10),2) -> 0 | AM7: =MIN(AL7,Sorted!$G$10) -> 0 | AN7: =MAX(0,MIN(AL7-AM7,$C7-(H7+L7+P7+T7+X7+AB7+AF7+AJ7))) -> 0 | AO7: =ROUND(AL7-AM7-AN7,2) -> 0 | AP7: =ROUND(AS6*(1+Sorted!$H$11),2) -> 0 | AQ7: =MIN(AP7,Sorted!$G$11) -> 0 | AR7: =MAX(0,MIN(AP7-AQ7,$C7-(H7+L7+P7+T7+X7+AB7+AF7+AJ7+AN7))) -> 0 | AS7: =ROUND(AP7-AQ7-AR7,2) -> 0
A8: 5 | B8: =EDATE('My Debts'!$C$7,A8-1) -> 46447 | C8: =MAX(0,'My Debts'!$E$6-(G8+K8+O8+S8+W8+AA8+AE8+AI8+AM8+AQ8)) -> 260 | D8: =(F8+J8+N8+R8+V8+Z8+AD8+AH8+AL8+AP8)-(I8+M8+Q8+U8+Y8+AC8+AG8+AK8+AO8+AS8) -> 730 | E8: =I8+M8+Q8+U8+Y8+AC8+AG8+AK8+AO8+AS8 -> 10869.07 | F8: =ROUND(I7*(1+Sorted!$H$2),2) -> 0 | G8: =MIN(F8,Sorted!$G$2) -> 0 | H8: =MAX(0,MIN(F8-G8,$C8-(0))) -> 0 | I8: =ROUND(F8-G8-H8,2) -> 0 | J8: =ROUND(M7*(1+Sorted!$H$3),2) -> 1283.35 | K8: =MIN(J8,Sorted!$G$3) -> 55 | L8: =MAX(0,MIN(J8-K8,$C8-(H8))) -> 260 | M8: =ROUND(J8-K8-L8,2) -> 968.35 | N8: =ROUND(Q7*(1+Sorted!$H$4),2) -> 3459.34 | O8: =MIN(N8,Sorted!$G$4) -> 240 | P8: =MAX(0,MIN(N8-O8,$C8-(H8+L8))) -> 0 | Q8: =ROUND(N8-O8-P8,2) -> 3219.34 | R8: =ROUND(U7*(1+Sorted!$H$5),2) -> 6856.38 | S8: =MIN(R8,Sorted!$G$5) -> 175 | T8: =MAX(0,MIN(R8-S8,$C8-(H8+L8+P8))) -> 0 | U8: =ROUND(R8-S8-T8,2) -> 6681.38 | V8: =ROUND(Y7*(1+Sorted!$H$6),2) -> 0 | W8: =MIN(V8,Sorted!$G$6) -> 0 | X8: =MAX(0,MIN(V8-W8,$C8-(H8+L8+P8+T8))) -> 0 | Y8: =ROUND(V8-W8-X8,2) -> 0 | Z8: =ROUND(AC7*(1+Sorted!$H$7),2) -> 0 | AA8: =MIN(Z8,Sorted!$G$7) -> 0 | AB8: =MAX(0,MIN(Z8-AA8,$C8-(H8+L8+P8+T8+X8))) -> 0 | AC8: =ROUND(Z8-AA8-AB8,2) -> 0 | AD8: =ROUND(AG7*(1+Sorted!$H$8),2) -> 0 | AE8: =MIN(AD8,Sorted!$G$8) -> 0 | AF8: =MAX(0,MIN(AD8-AE8,$C8-(H8+L8+P8+T8+X8+AB8))) -> 0 | AG8: =ROUND(AD8-AE8-AF8,2) -> 0 | AH8: =ROUND(AK7*(1+Sorted!$H$9),2) -> 0 | AI8: =MIN(AH8,Sorted!$G$9) -> 0 | AJ8: =MAX(0,MIN(AH8-AI8,$C8-(H8+L8+P8+T8+X8+AB8+AF8))) -> 0 | AK8: =ROUND(AH8-AI8-AJ8,2) -> 0 | AL8: =ROUND(AO7*(1+Sorted!$H$10),2) -> 0 | AM8: =MIN(AL8,Sorted!$G$10) -> 0 | AN8: =MAX(0,MIN(AL8-AM8,$C8-(H8+L8+P8+T8+X8+AB8+AF8+AJ8))) -> 0 | AO8: =ROUND(AL8-AM8-AN8,2) -> 0 | AP8: =ROUND(AS7*(1+Sorted!$H$11),2) -> 0 | AQ8: =MIN(AP8,Sorted!$G$11) -> 0 | AR8: =MAX(0,MIN(AP8-AQ8,$C8-(H8+L8+P8+T8+X8+AB8+AF8+AJ8+AN8))) -> 0 | AS8: =ROUND(AP8-AQ8-AR8,2) -> 0
A9: 6 | B9: =EDATE('My Debts'!$C$7,A9-1) -> 46478 | C9: =MAX(0,'My Debts'!$E$6-(G9+K9+O9+S9+W9+AA9+AE9+AI9+AM9+AQ9)) -> 260 | D9: =(F9+J9+N9+R9+V9+Z9+AD9+AH9+AL9+AP9)-(I9+M9+Q9+U9+Y9+AC9+AG9+AK9+AO9+AS9) -> 730 | E9: =I9+M9+Q9+U9+Y9+AC9+AG9+AK9+AO9+AS9 -> 10322.26 | F9: =ROUND(I8*(1+Sorted!$H$2),2) -> 0 | G9: =MIN(F9,Sorted!$G$2) -> 0 | H9: =MAX(0,MIN(F9-G9,$C9-(0))) -> 0 | I9: =ROUND(F9-G9-H9,2) -> 0 | J9: =ROUND(M8*(1+Sorted!$H$3),2) -> 992.55 | K9: =MIN(J9,Sorted!$G$3) -> 55 | L9: =MAX(0,MIN(J9-K9,$C9-(H9))) -> 260 | M9: =ROUND(J9-K9-L9,2) -> 677.55 | N9: =ROUND(Q8*(1+Sorted!$H$4),2) -> 3239.19 | O9: =MIN(N9,Sorted!$G$4) -> 240 | P9: =MAX(0,MIN(N9-O9,$C9-(H9+L9))) -> 0 | Q9: =ROUND(N9-O9-P9,2) -> 2999.19 | R9: =ROUND(U8*(1+Sorted!$H$5),2) -> 6820.52 | S9: =MIN(R9,Sorted!$G$5) -> 175 | T9: =MAX(0,MIN(R9-S9,$C9-(H9+L9+P9))) -> 0 | U9: =ROUND(R9-S9-T9,2) -> 6645.52 | V9: =ROUND(Y8*(1+Sorted!$H$6),2) -> 0 | W9: =MIN(V9,Sorted!$G$6) -> 0 | X9: =MAX(0,MIN(V9-W9,$C9-(H9+L9+P9+T9))) -> 0 | Y9: =ROUND(V9-W9-X9,2) -> 0 | Z9: =ROUND(AC8*(1+Sorted!$H$7),2) -> 0 | AA9: =MIN(Z9,Sorted!$G$7) -> 0 | AB9: =MAX(0,MIN(Z9-AA9,$C9-(H9+L9+P9+T9+X9))) -> 0 | AC9: =ROUND(Z9-AA9-AB9,2) -> 0 | AD9: =ROUND(AG8*(1+Sorted!$H$8),2) -> 0 | AE9: =MIN(AD9,Sorted!$G$8) -> 0 | AF9: =MAX(0,MIN(AD9-AE9,$C9-(H9+L9+P9+T9+X9+AB9))) -> 0 | AG9: =ROUND(AD9-AE9-AF9,2) -> 0 | AH9: =ROUND(AK8*(1+Sorted!$H$9),2) -> 0 | AI9: =MIN(AH9,Sorted!$G$9) -> 0 | AJ9: =MAX(0,MIN(AH9-AI9,$C9-(H9+L9+P9+T9+X9+AB9+AF9))) -> 0 | AK9: =ROUND(AH9-AI9-AJ9,2) -> 0 | AL9: =ROUND(AO8*(1+Sorted!$H$10),2) -> 0 | AM9: =MIN(AL9,Sorted!$G$10) -> 0 | AN9: =MAX(0,MIN(AL9-AM9,$C9-(H9+L9+P9+T9+X9+AB9+AF9+AJ9))) -> 0 | AO9: =ROUND(AL9-AM9-AN9,2) -> 0 | AP9: =ROUND(AS8*(1+Sorted!$H$11),2) -> 0 | AQ9: =MIN(AP9,Sorted!$G$11) -> 0 | AR9: =MAX(0,MIN(AP9-AQ9,$C9-(H9+L9+P9+T9+X9+AB9+AF9+AJ9+AN9))) -> 0 | AS9: =ROUND(AP9-AQ9-AR9,2) -> 0
A10: 7 | B10: =EDATE('My Debts'!$C$7,A10-1) -> 46508 | C10: =MAX(0,'My Debts'!$E$6-(G10+K10+O10+S10+W10+AA10+AE10+AI10+AM10+AQ10)) -> 260 | D10: =(F10+J10+N10+R10+V10+Z10+AD10+AH10+AL10+AP10)-(I10+M10+Q10+U10+Y10+AC10+AG10+AK10+AO10+AS10) -> 730 | E10: =I10+M10+Q10+U10+Y10+AC10+AG10+AK10+AO10+AS10 -> 9766.08 | F10: =ROUND(I9*(1+Sorted!$H$2),2) -> 0 | G10: =MIN(F10,Sorted!$G$2) -> 0 | H10: =MAX(0,MIN(F10-G10,$C10-(0))) -> 0 | I10: =ROUND(F10-G10-H10,2) -> 0 | J10: =ROUND(M9*(1+Sorted!$H$3),2) -> 694.48 | K10: =MIN(J10,Sorted!$G$3) -> 55 | L10: =MAX(0,MIN(J10-K10,$C10-(H10))) -> 260 | M10: =ROUND(J10-K10-L10,2) -> 379.48 | N10: =ROUND(Q9*(1+Sorted!$H$4),2) -> 3017.69 | O10: =MIN(N10,Sorted!$G$4) -> 240 | P10: =MAX(0,MIN(N10-O10,$C10-(H10+L10))) -> 0 | Q10: =ROUND(N10-O10-P10,2) -> 2777.69 | R10: =ROUND(U9*(1+Sorted!$H$5),2) -> 6783.91 | S10: =MIN(R10,Sorted!$G$5) -> 175 | T10: =MAX(0,MIN(R10-S10,$C10-(H10+L10+P10))) -> 0 | U10: =ROUND(R10-S10-T10,2) -> 6608.91 | V10: =ROUND(Y9*(1+Sorted!$H$6),2) -> 0 | W10: =MIN(V10,Sorted!$G$6) -> 0 | X10: =MAX(0,MIN(V10-W10,$C10-(H10+L10+P10+T10))) -> 0 | Y10: =ROUND(V10-W10-X10,2) -> 0 | Z10: =ROUND(AC9*(1+Sorted!$H$7),2) -> 0 | AA10: =MIN(Z10,Sorted!$G$7) -> 0 | AB10: =MAX(0,MIN(Z10-AA10,$C10-(H10+L10+P10+T10+X10))) -> 0 | AC10: =ROUND(Z10-AA10-AB10,2) -> 0 | AD10: =ROUND(AG9*(1+Sorted!$H$8),2) -> 0 | AE10: =MIN(AD10,Sorted!$G$8) -> 0 | AF10: =MAX(0,MIN(AD10-AE10,$C10-(H10+L10+P10+T10+X10+AB10))) -> 0 | AG10: =ROUND(AD10-AE10-AF10,2) -> 0 | AH10: =ROUND(AK9*(1+Sorted!$H$9),2) -> 0 | AI10: =MIN(AH10,Sorted!$G$9) -> 0 | AJ10: =MAX(0,MIN(AH10-AI10,$C10-(H10+L10+P10+T10+X10+AB10+AF10))) -> 0 | AK10: =ROUND(AH10-AI10-AJ10,2) -> 0 | AL10: =ROUND(AO9*(1+Sorted!$H$10),2) -> 0 | AM10: =MIN(AL10,Sorted!$G$10) -> 0 | AN10: =MAX(0,MIN(AL10-AM10,$C10-(H10+L10+P10+T10+X10+AB10+AF10+AJ10))) -> 0 | AO10: =ROUND(AL10-AM10-AN10,2) -> 0 | AP10: =ROUND(AS9*(1+Sorted!$H$11),2) -> 0 | AQ10: =MIN(AP10,Sorted!$G$11) -> 0 | AR10: =MAX(0,MIN(AP10-AQ10,$C10-(H10+L10+P10+T10+X10+AB10+AF10+AJ10+AN10))) -> 0 | AS10: =ROUND(AP10-AQ10-AR10,2) -> 0
A11: 8 | B11: =EDATE('My Debts'!$C$7,A11-1) -> 46539 | C11: =MAX(0,'My Debts'!$E$6-(G11+K11+O11+S11+W11+AA11+AE11+AI11+AM11+AQ11)) -> 260 | D11: =(F11+J11+N11+R11+V11+Z11+AD11+AH11+AL11+AP11)-(I11+M11+Q11+U11+Y11+AC11+AG11+AK11+AO11+AS11) -> 730 | E11: =I11+M11+Q11+U11+Y11+AC11+AG11+AK11+AO11+AS11 -> 9200.32 | F11: =ROUND(I10*(1+Sorted!$H$2),2) -> 0 | G11: =MIN(F11,Sorted!$G$2) -> 0 | H11: =MAX(0,MIN(F11-G11,$C11-(0))) -> 0 | I11: =ROUND(F11-G11-H11,2) -> 0 | J11: =ROUND(M10*(1+Sorted!$H$3),2) -> 388.96 | K11: =MIN(J11,Sorted!$G$3) -> 55 | L11: =MAX(0,MIN(J11-K11,$C11-(H11))) -> 260 | M11: =ROUND(J11-K11-L11,2) -> 73.96 | N11: =ROUND(Q10*(1+Sorted!$H$4),2) -> 2794.82 | O11: =MIN(N11,Sorted!$G$4) -> 240 | P11: =MAX(0,MIN(N11-O11,$C11-(H11+L11))) -> 0 | Q11: =ROUND(N11-O11-P11,2) -> 2554.82 | R11: =ROUND(U10*(1+Sorted!$H$5),2) -> 6746.54 | S11: =MIN(R11,Sorted!$G$5) -> 175 | T11: =MAX(0,MIN(R11-S11,$C11-(H11+L11+P11))) -> 0 | U11: =ROUND(R11-S11-T11,2) -> 6571.54 | V11: =ROUND(Y10*(1+Sorted!$H$6),2) -> 0 | W11: =MIN(V11,Sorted!$G$6) -> 0 | X11: =MAX(0,MIN(V11-W11,$C11-(H11+L11+P11+T11))) -> 0 | Y11: =ROUND(V11-W11-X11,2) -> 0 | Z11: =ROUND(AC10*(1+Sorted!$H$7),2) -> 0 | AA11: =MIN(Z11,Sorted!$G$7) -> 0 | AB11: =MAX(0,MIN(Z11-AA11,$C11-(H11+L11+P11+T11+X11))) -> 0 | AC11: =ROUND(Z11-AA11-AB11,2) -> 0 | AD11: =ROUND(AG10*(1+Sorted!$H$8),2) -> 0 | AE11: =MIN(AD11,Sorted!$G$8) -> 0 | AF11: =MAX(0,MIN(AD11-AE11,$C11-(H11+L11+P11+T11+X11+AB11))) -> 0 | AG11: =ROUND(AD11-AE11-AF11,2) -> 0 | AH11: =ROUND(AK10*(1+Sorted!$H$9),2) -> 0 | AI11: =MIN(AH11,Sorted!$G$9) -> 0 | AJ11: =MAX(0,MIN(AH11-AI11,$C11-(H11+L11+P11+T11+X11+AB11+AF11))) -> 0 | AK11: =ROUND(AH11-AI11-AJ11,2) -> 0 | AL11: =ROUND(AO10*(1+Sorted!$H$10),2) -> 0 | AM11: =MIN(AL11,Sorted!$G$10) -> 0 | AN11: =MAX(0,MIN(AL11-AM11,$C11-(H11+L11+P11+T11+X11+AB11+AF11+AJ11))) -> 0 | AO11: =ROUND(AL11-AM11-AN11,2) -> 0 | AP11: =ROUND(AS10*(1+Sorted!$H$11),2) -> 0 | AQ11: =MIN(AP11,Sorted!$G$11) -> 0 | AR11: =MAX(0,MIN(AP11-AQ11,$C11-(H11+L11+P11+T11+X11+AB11+AF11+AJ11+AN11))) -> 0 | AS11: =ROUND(AP11-AQ11-AR11,2) -> 0
A12: 9 | B12: =EDATE('My Debts'!$C$7,A12-1) -> 46569 | C12: =MAX(0,'My Debts'!$E$6-(G12+K12+O12+S12+W12+AA12+AE12+AI12+AM12+AQ12)) -> 260 | D12: =(F12+J12+N12+R12+V12+Z12+AD12+AH12+AL12+AP12)-(I12+M12+Q12+U12+Y12+AC12+AG12+AK12+AO12+AS12) -> 730 | E12: =I12+M12+Q12+U12+Y12+AC12+AG12+AK12+AO12+AS12 -> 8624.77 | F12: =ROUND(I11*(1+Sorted!$H$2),2) -> 0 | G12: =MIN(F12,Sorted!$G$2) -> 0 | H12: =MAX(0,MIN(F12-G12,$C12-(0))) -> 0 | I12: =ROUND(F12-G12-H12,2) -> 0 | J12: =ROUND(M11*(1+Sorted!$H$3),2) -> 75.81 | K12: =MIN(J12,Sorted!$G$3) -> 55 | L12: =MAX(0,MIN(J12-K12,$C12-(H12))) -> 20.81 | M12: =ROUND(J12-K12-L12,2) -> 0 | N12: =ROUND(Q11*(1+Sorted!$H$4),2) -> 2570.57 | O12: =MIN(N12,Sorted!$G$4) -> 240 | P12: =MAX(0,MIN(N12-O12,$C12-(H12+L12))) -> 239.19 | Q12: =ROUND(N12-O12-P12,2) -> 2091.38 | R12: =ROUND(U11*(1+Sorted!$H$5),2) -> 6708.39 | S12: =MIN(R12,Sorted!$G$5) -> 175 | T12: =MAX(0,MIN(R12-S12,$C12-(H12+L12+P12))) -> 0 | U12: =ROUND(R12-S12-T12,2) -> 6533.39 | V12: =ROUND(Y11*(1+Sorted!$H$6),2) -> 0 | W12: =MIN(V12,Sorted!$G$6) -> 0 | X12: =MAX(0,MIN(V12-W12,$C12-(H12+L12+P12+T12))) -> 0 | Y12: =ROUND(V12-W12-X12,2) -> 0 | Z12: =ROUND(AC11*(1+Sorted!$H$7),2) -> 0 | AA12: =MIN(Z12,Sorted!$G$7) -> 0 | AB12: =MAX(0,MIN(Z12-AA12,$C12-(H12+L12+P12+T12+X12))) -> 0 | AC12: =ROUND(Z12-AA12-AB12,2) -> 0 | AD12: =ROUND(AG11*(1+Sorted!$H$8),2) -> 0 | AE12: =MIN(AD12,Sorted!$G$8) -> 0 | AF12: =MAX(0,MIN(AD12-AE12,$C12-(H12+L12+P12+T12+X12+AB12))) -> 0 | AG12: =ROUND(AD12-AE12-AF12,2) -> 0 | AH12: =ROUND(AK11*(1+Sorted!$H$9),2) -> 0 | AI12: =MIN(AH12,Sorted!$G$9) -> 0 | AJ12: =MAX(0,MIN(AH12-AI12,$C12-(H12+L12+P12+T12+X12+AB12+AF12))) -> 0 | AK12: =ROUND(AH12-AI12-AJ12,2) -> 0 | AL12: =ROUND(AO11*(1+Sorted!$H$10),2) -> 0 | AM12: =MIN(AL12,Sorted!$G$10) -> 0 | AN12: =MAX(0,MIN(AL12-AM12,$C12-(H12+L12+P12+T12+X12+AB12+AF12+AJ12))) -> 0 | AO12: =ROUND(AL12-AM12-AN12,2) -> 0 | AP12: =ROUND(AS11*(1+Sorted!$H$11),2) -> 0 | AQ12: =MIN(AP12,Sorted!$G$11) -> 0 | AR12: =MAX(0,MIN(AP12-AQ12,$C12-(H12+L12+P12+T12+X12+AB12+AF12+AJ12+AN12))) -> 0 | AS12: =ROUND(AP12-AQ12-AR12,2) -> 0
A13: 10 | B13: =EDATE('My Debts'!$C$7,A13-1) -> 46600 | C13: =MAX(0,'My Debts'!$E$6-(G13+K13+O13+S13+W13+AA13+AE13+AI13+AM13+AQ13)) -> 315 | D13: =(F13+J13+N13+R13+V13+Z13+AD13+AH13+AL13+AP13)-(I13+M13+Q13+U13+Y13+AC13+AG13+AK13+AO13+AS13) -> 730 | E13: =I13+M13+Q13+U13+Y13+AC13+AG13+AK13+AO13+AS13 -> 8043.73 | F13: =ROUND(I12*(1+Sorted!$H$2),2) -> 0 | G13: =MIN(F13,Sorted!$G$2) -> 0 | H13: =MAX(0,MIN(F13-G13,$C13-(0))) -> 0 | I13: =ROUND(F13-G13-H13,2) -> 0 | J13: =ROUND(M12*(1+Sorted!$H$3),2) -> 0 | K13: =MIN(J13,Sorted!$G$3) -> 0 | L13: =MAX(0,MIN(J13-K13,$C13-(H13))) -> 0 | M13: =ROUND(J13-K13-L13,2) -> 0 | N13: =ROUND(Q12*(1+Sorted!$H$4),2) -> 2104.28 | O13: =MIN(N13,Sorted!$G$4) -> 240 | P13: =MAX(0,MIN(N13-O13,$C13-(H13+L13))) -> 315 | Q13: =ROUND(N13-O13-P13,2) -> 1549.28 | R13: =ROUND(U12*(1+Sorted!$H$5),2) -> 6669.45 | S13: =MIN(R13,Sorted!$G$5) -> 175 | T13: =MAX(0,MIN(R13-S13,$C13-(H13+L13+P13))) -> 0 | U13: =ROUND(R13-S13-T13,2) -> 6494.45 | V13: =ROUND(Y12*(1+Sorted!$H$6),2) -> 0 | W13: =MIN(V13,Sorted!$G$6) -> 0 | X13: =MAX(0,MIN(V13-W13,$C13-(H13+L13+P13+T13))) -> 0 | Y13: =ROUND(V13-W13-X13,2) -> 0 | Z13: =ROUND(AC12*(1+Sorted!$H$7),2) -> 0 | AA13: =MIN(Z13,Sorted!$G$7) -> 0 | AB13: =MAX(0,MIN(Z13-AA13,$C13-(H13+L13+P13+T13+X13))) -> 0 | AC13: =ROUND(Z13-AA13-AB13,2) -> 0 | AD13: =ROUND(AG12*(1+Sorted!$H$8),2) -> 0 | AE13: =MIN(AD13,Sorted!$G$8) -> 0 | AF13: =MAX(0,MIN(AD13-AE13,$C13-(H13+L13+P13+T13+X13+AB13))) -> 0 | AG13: =ROUND(AD13-AE13-AF13,2) -> 0 | AH13: =ROUND(AK12*(1+Sorted!$H$9),2) -> 0 | AI13: =MIN(AH13,Sorted!$G$9) -> 0 | AJ13: =MAX(0,MIN(AH13-AI13,$C13-(H13+L13+P13+T13+X13+AB13+AF13))) -> 0 | AK13: =ROUND(AH13-AI13-AJ13,2) -> 0 | AL13: =ROUND(AO12*(1+Sorted!$H$10),2) -> 0 | AM13: =MIN(AL13,Sorted!$G$10) -> 0 | AN13: =MAX(0,MIN(AL13-AM13,$C13-(H13+L13+P13+T13+X13+AB13+AF13+AJ13))) -> 0 | AO13: =ROUND(AL13-AM13-AN13,2) -> 0 | AP13: =ROUND(AS12*(1+Sorted!$H$11),2) -> 0 | AQ13: =MIN(AP13,Sorted!$G$11) -> 0 | AR13: =MAX(0,MIN(AP13-AQ13,$C13-(H13+L13+P13+T13+X13+AB13+AF13+AJ13+AN13))) -> 0 | AS13: =ROUND(AP13-AQ13-AR13,2) -> 0
A14: 11 | B14: =EDATE('My Debts'!$C$7,A14-1) -> 46631 | C14: =MAX(0,'My Debts'!$E$6-(G14+K14+O14+S14+W14+AA14+AE14+AI14+AM14+AQ14)) -> 315 | D14: =(F14+J14+N14+R14+V14+Z14+AD14+AH14+AL14+AP14)-(I14+M14+Q14+U14+Y14+AC14+AG14+AK14+AO14+AS14) -> 730 | E14: =I14+M14+Q14+U14+Y14+AC14+AG14+AK14+AO14+AS14 -> 7458.53 | F14: =ROUND(I13*(1+Sorted!$H$2),2) -> 0 | G14: =MIN(F14,Sorted!$G$2) -> 0 | H14: =MAX(0,MIN(F14-G14,$C14-(0))) -> 0 | I14: =ROUND(F14-G14-H14,2) -> 0 | J14: =ROUND(M13*(1+Sorted!$H$3),2) -> 0 | K14: =MIN(J14,Sorted!$G$3) -> 0 | L14: =MAX(0,MIN(J14-K14,$C14-(H14))) -> 0 | M14: =ROUND(J14-K14-L14,2) -> 0 | N14: =ROUND(Q13*(1+Sorted!$H$4),2) -> 1558.83 | O14: =MIN(N14,Sorted!$G$4) -> 240 | P14: =MAX(0,MIN(N14-O14,$C14-(H14+L14))) -> 315 | Q14: =ROUND(N14-O14-P14,2) -> 1003.83 | R14: =ROUND(U13*(1+Sorted!$H$5),2) -> 6629.7 | S14: =MIN(R14,Sorted!$G$5) -> 175 | T14: =MAX(0,MIN(R14-S14,$C14-(H14+L14+P14))) -> 0 | U14: =ROUND(R14-S14-T14,2) -> 6454.7 | V14: =ROUND(Y13*(1+Sorted!$H$6),2) -> 0 | W14: =MIN(V14,Sorted!$G$6) -> 0 | X14: =MAX(0,MIN(V14-W14,$C14-(H14+L14+P14+T14))) -> 0 | Y14: =ROUND(V14-W14-X14,2) -> 0 | Z14: =ROUND(AC13*(1+Sorted!$H$7),2) -> 0 | AA14: =MIN(Z14,Sorted!$G$7) -> 0 | AB14: =MAX(0,MIN(Z14-AA14,$C14-(H14+L14+P14+T14+X14))) -> 0 | AC14: =ROUND(Z14-AA14-AB14,2) -> 0 | AD14: =ROUND(AG13*(1+Sorted!$H$8),2) -> 0 | AE14: =MIN(AD14,Sorted!$G$8) -> 0 | AF14: =MAX(0,MIN(AD14-AE14,$C14-(H14+L14+P14+T14+X14+AB14))) -> 0 | AG14: =ROUND(AD14-AE14-AF14,2) -> 0 | AH14: =ROUND(AK13*(1+Sorted!$H$9),2) -> 0 | AI14: =MIN(AH14,Sorted!$G$9) -> 0 | AJ14: =MAX(0,MIN(AH14-AI14,$C14-(H14+L14+P14+T14+X14+AB14+AF14))) -> 0 | AK14: =ROUND(AH14-AI14-AJ14,2) -> 0 | AL14: =ROUND(AO13*(1+Sorted!$H$10),2) -> 0 | AM14: =MIN(AL14,Sorted!$G$10) -> 0 | AN14: =MAX(0,MIN(AL14-AM14,$C14-(H14+L14+P14+T14+X14+AB14+AF14+AJ14))) -> 0 | AO14: =ROUND(AL14-AM14-AN14,2) -> 0 | AP14: =ROUND(AS13*(1+Sorted!$H$11),2) -> 0 | AQ14: =MIN(AP14,Sorted!$G$11) -> 0 | AR14: =MAX(0,MIN(AP14-AQ14,$C14-(H14+L14+P14+T14+X14+AB14+AF14+AJ14+AN14))) -> 0 | AS14: =ROUND(AP14-AQ14-AR14,2) -> 0
A15: 12 | B15: =EDATE('My Debts'!$C$7,A15-1) -> 46661 | C15: =MAX(0,'My Debts'!$E$6-(G15+K15+O15+S15+W15+AA15+AE15+AI15+AM15+AQ15)) -> 315 | D15: =(F15+J15+N15+R15+V15+Z15+AD15+AH15+AL15+AP15)-(I15+M15+Q15+U15+Y15+AC15+AG15+AK15+AO15+AS15) -> 730 | E15: =I15+M15+Q15+U15+Y15+AC15+AG15+AK15+AO15+AS15 -> 6869.14 | F15: =ROUND(I14*(1+Sorted!$H$2),2) -> 0 | G15: =MIN(F15,Sorted!$G$2) -> 0 | H15: =MAX(0,MIN(F15-G15,$C15-(0))) -> 0 | I15: =ROUND(F15-G15-H15,2) -> 0 | J15: =ROUND(M14*(1+Sorted!$H$3),2) -> 0 | K15: =MIN(J15,Sorted!$G$3) -> 0 | L15: =MAX(0,MIN(J15-K15,$C15-(H15))) -> 0 | M15: =ROUND(J15-K15-L15,2) -> 0 | N15: =ROUND(Q14*(1+Sorted!$H$4),2) -> 1010.02 | O15: =MIN(N15,Sorted!$G$4) -> 240 | P15: =MAX(0,MIN(N15-O15,$C15-(H15+L15))) -> 315 | Q15: =ROUND(N15-O15-P15,2) -> 455.02 | R15: =ROUND(U14*(1+Sorted!$H$5),2) -> 6589.12 | S15: =MIN(R15,Sorted!$G$5) -> 175 | T15: =MAX(0,MIN(R15-S15,$C15-(H15+L15+P15))) -> 0 | U15: =ROUND(R15-S15-T15,2) -> 6414.12 | V15: =ROUND(Y14*(1+Sorted!$H$6),2) -> 0 | W15: =MIN(V15,Sorted!$G$6) -> 0 | X15: =MAX(0,MIN(V15-W15,$C15-(H15+L15+P15+T15))) -> 0 | Y15: =ROUND(V15-W15-X15,2) -> 0 | Z15: =ROUND(AC14*(1+Sorted!$H$7),2) -> 0 | AA15: =MIN(Z15,Sorted!$G$7) -> 0 | AB15: =MAX(0,MIN(Z15-AA15,$C15-(H15+L15+P15+T15+X15))) -> 0 | AC15: =ROUND(Z15-AA15-AB15,2) -> 0 | AD15: =ROUND(AG14*(1+Sorted!$H$8),2) -> 0 | AE15: =MIN(AD15,Sorted!$G$8) -> 0 | AF15: =MAX(0,MIN(AD15-AE15,$C15-(H15+L15+P15+T15+X15+AB15))) -> 0 | AG15: =ROUND(AD15-AE15-AF15,2) -> 0 | AH15: =ROUND(AK14*(1+Sorted!$H$9),2) -> 0 | AI15: =MIN(AH15,Sorted!$G$9) -> 0 | AJ15: =MAX(0,MIN(AH15-AI15,$C15-(H15+L15+P15+T15+X15+AB15+AF15))) -> 0 | AK15: =ROUND(AH15-AI15-AJ15,2) -> 0 | AL15: =ROUND(AO14*(1+Sorted!$H$10),2) -> 0 | AM15: =MIN(AL15,Sorted!$G$10) -> 0 | AN15: =MAX(0,MIN(AL15-AM15,$C15-(H15+L15+P15+T15+X15+AB15+AF15+AJ15))) -> 0 | AO15: =ROUND(AL15-AM15-AN15,2) -> 0 | AP15: =ROUND(AS14*(1+Sorted!$H$11),2) -> 0 | AQ15: =MIN(AP15,Sorted!$G$11) -> 0 | AR15: =MAX(0,MIN(AP15-AQ15,$C15-(H15+L15+P15+T15+X15+AB15+AF15+AJ15+AN15))) -> 0 | AS15: =ROUND(AP15-AQ15-AR15,2) -> 0
A16: 13 | B16: =EDATE('My Debts'!$C$7,A16-1) -> 46692 | C16: =MAX(0,'My Debts'!$E$6-(G16+K16+O16+S16+W16+AA16+AE16+AI16+AM16+AQ16)) -> 315 | D16: =(F16+J16+N16+R16+V16+Z16+AD16+AH16+AL16+AP16)-(I16+M16+Q16+U16+Y16+AC16+AG16+AK16+AO16+AS16) -> 730 | E16: =I16+M16+Q16+U16+Y16+AC16+AG16+AK16+AO16+AS16 -> 6275.52 | F16: =ROUND(I15*(1+Sorted!$H$2),2) -> 0 | G16: =MIN(F16,Sorted!$G$2) -> 0 | H16: =MAX(0,MIN(F16-G16,$C16-(0))) -> 0 | I16: =ROUND(F16-G16-H16,2) -> 0 | J16: =ROUND(M15*(1+Sorted!$H$3),2) -> 0 | K16: =MIN(J16,Sorted!$G$3) -> 0 | L16: =MAX(0,MIN(J16-K16,$C16-(H16))) -> 0 | M16: =ROUND(J16-K16-L16,2) -> 0 | N16: =ROUND(Q15*(1+Sorted!$H$4),2) -> 457.83 | O16: =MIN(N16,Sorted!$G$4) -> 240 | P16: =MAX(0,MIN(N16-O16,$C16-(H16+L16))) -> 217.83 | Q16: =ROUND(N16-O16-P16,2) -> 0 | R16: =ROUND(U15*(1+Sorted!$H$5),2) -> 6547.69 | S16: =MIN(R16,Sorted!$G$5) -> 175 | T16: =MAX(0,MIN(R16-S16,$C16-(H16+L16+P16))) -> 97.17 | U16: =ROUND(R16-S16-T16,2) -> 6275.52 | V16: =ROUND(Y15*(1+Sorted!$H$6),2) -> 0 | W16: =MIN(V16,Sorted!$G$6) -> 0 | X16: =MAX(0,MIN(V16-W16,$C16-(H16+L16+P16+T16))) -> 0 | Y16: =ROUND(V16-W16-X16,2) -> 0 | Z16: =ROUND(AC15*(1+Sorted!$H$7),2) -> 0 | AA16: =MIN(Z16,Sorted!$G$7) -> 0 | AB16: =MAX(0,MIN(Z16-AA16,$C16-(H16+L16+P16+T16+X16))) -> 0 | AC16: =ROUND(Z16-AA16-AB16,2) -> 0 | AD16: =ROUND(AG15*(1+Sorted!$H$8),2) -> 0 | AE16: =MIN(AD16,Sorted!$G$8) -> 0 | AF16: =MAX(0,MIN(AD16-AE16,$C16-(H16+L16+P16+T16+X16+AB16))) -> 0 | AG16: =ROUND(AD16-AE16-AF16,2) -> 0 | AH16: =ROUND(AK15*(1+Sorted!$H$9),2) -> 0 | AI16: =MIN(AH16,Sorted!$G$9) -> 0 | AJ16: =MAX(0,MIN(AH16-AI16,$C16-(H16+L16+P16+T16+X16+AB16+AF16))) -> 0 | AK16: =ROUND(AH16-AI16-AJ16,2) -> 0 | AL16: =ROUND(AO15*(1+Sorted!$H$10),2) -> 0 | AM16: =MIN(AL16,Sorted!$G$10) -> 0 | AN16: =MAX(0,MIN(AL16-AM16,$C16-(H16+L16+P16+T16+X16+AB16+AF16+AJ16))) -> 0 | AO16: =ROUND(AL16-AM16-AN16,2) -> 0 | AP16: =ROUND(AS15*(1+Sorted!$H$11),2) -> 0 | AQ16: =MIN(AP16,Sorted!$G$11) -> 0 | AR16: =MAX(0,MIN(AP16-AQ16,$C16-(H16+L16+P16+T16+X16+AB16+AF16+AJ16+AN16))) -> 0 | AS16: =ROUND(AP16-AQ16-AR16,2) -> 0
... A243: 240 | B243: =EDATE('My Debts'!$C$7,A243-1) -> 53601 | C243: =MAX(0,'My Debts'!$E$6-(G243+K243+O243+S243+W243+AA243+AE243+AI243+AM243+AQ243)) -> 730 | D243: =(F243+J243+N243+R243+V243+Z243+AD243+AH243+AL243+AP243)-(I243+M243+Q243+U243+Y243+AC243+AG243+AK243+AO243+AS243) -> 0 | E243: =I243+M243+Q243+U243+Y243+AC243+AG243+AK243+AO243+AS243 -> 0 | F243: =ROUND(I242*(1+Sorted!$H$2),2) -> 0 | G243: =MIN(F243,Sorted!$G$2) -> 0 | H243: =MAX(0,MIN(F243-G243,$C243-(0))) -> 0 | I243: =ROUND(F243-G243-H243,2) -> 0 | J243: =ROUND(M242*(1+Sorted!$H$3),2) -> 0 | K243: =MIN(J243,Sorted!$G$3) -> 0 | L243: =MAX(0,MIN(J243-K243,$C243-(H243))) -> 0 | M243: =ROUND(J243-K243-L243,2) -> 0 | N243: =ROUND(Q242*(1+Sorted!$H$4),2) -> 0 | O243: =MIN(N243,Sorted!$G$4) -> 0 | P243: =MAX(0,MIN(N243-O243,$C243-(H243+L243))) -> 0 | Q243: =ROUND(N243-O243-P243,2) -> 0 | R243: =ROUND(U242*(1+Sorted!$H$5),2) -> 0 | S243: =MIN(R243,Sorted!$G$5) -> 0 | T243: =MAX(0,MIN(R243-S243,$C243-(H243+L243+P243))) -> 0 | U243: =ROUND(R243-S243-T243,2) -> 0 | V243: =ROUND(Y242*(1+Sorted!$H$6),2) -> 0 | W243: =MIN(V243,Sorted!$G$6) -> 0 | X243: =MAX(0,MIN(V243-W243,$C243-(H243+L243+P243+T243))) -> 0 | Y243: =ROUND(V243-W243-X243,2) -> 0 | Z243: =ROUND(AC242*(1+Sorted!$H$7),2) -> 0 | AA243: =MIN(Z243,Sorted!$G$7) -> 0 | AB243: =MAX(0,MIN(Z243-AA243,$C243-(H243+L243+P243+T243+X243))) -> 0 | AC243: =ROUND(Z243-AA243-AB243,2) -> 0 | AD243: =ROUND(AG242*(1+Sorted!$H$8),2) -> 0 | AE243: =MIN(AD243,Sorted!$G$8) -> 0 | AF243: =MAX(0,MIN(AD243-AE243,$C243-(H243+L243+P243+T243+X243+AB243))) -> 0 | AG243: =ROUND(AD243-AE243-AF243,2) -> 0 | AH243: =ROUND(AK242*(1+Sorted!$H$9),2) -> 0 | AI243: =MIN(AH243,Sorted!$G$9) -> 0 | AJ243: =MAX(0,MIN(AH243-AI243,$C243-(H243+L243+P243+T243+X243+AB243+AF243))) -> 0 | AK243: =ROUND(AH243-AI243-AJ243,2) -> 0 | AL243: =ROUND(AO242*(1+Sorted!$H$10),2) -> 0 | AM243: =MIN(AL243,Sorted!$G$10) -> 0 | AN243: =MAX(0,MIN(AL243-AM243,$C243-(H243+L243+P243+T243+X243+AB243+AF243+AJ243))) -> 0 | AO243: =ROUND(AL243-AM243-AN243,2) -> 0 | AP243: =ROUND(AS242*(1+Sorted!$H$11),2) -> 0 | AQ243: =MIN(AP243,Sorted!$G$11) -> 0 | AR243: =MAX(0,MIN(AP243-AQ243,$C243-(H243+L243+P243+T243+X243+AB243+AF243+AJ243+AN243))) -> 0 | AS243: =ROUND(AP243-AQ243-AR243,2) -> 0

Sheet MinOnly
A1: Minimum payments only (for comparison)
F2: =IF(Sorted!$D$2="","",Sorted!$D$2) -> Personal loan | J2: =IF(Sorted!$D$3="","",Sorted!$D$3) -> Store card | N2: =IF(Sorted!$D$4="","",Sorted!$D$4) -> Car loan | R2: =IF(Sorted!$D$5="","",Sorted!$D$5) -> Visa credit card | V2: =IF(Sorted!$D$6="","",Sorted!$D$6) | Z2: =IF(Sorted!$D$7="","",Sorted!$D$7) | AD2: =IF(Sorted!$D$8="","",Sorted!$D$8) | AH2: =IF(Sorted!$D$9="","",Sorted!$D$9) | AL2: =IF(Sorted!$D$10="","",Sorted!$D$10) | AP2: =IF(Sorted!$D$11="","",Sorted!$D$11)
A3: Month | B3: Date | C3: Extra to allocate | D3: Total paid | E3: Total balance | F3: After interest | G3: Minimum | H3: Extra | I3: Balance | J3: After interest | K3: Minimum | L3: Extra | M3: Balance | N3: After interest | O3: Minimum | P3: Extra | Q3: Balance | R3: After interest | S3: Minimum | T3: Extra | U3: Balance | V3: After interest | W3: Minimum | X3: Extra | Y3: Balance | Z3: After interest | AA3: Minimum | AB3: Extra | AC3: Balance | AD3: After interest | AE3: Minimum | AF3: Extra | AG3: Balance | AH3: After interest | AI3: Minimum | AJ3: Extra | AK3: Balance | AL3: After interest | AM3: Minimum | AN3: Extra | AO3: Balance | AP3: After interest | AQ3: Minimum | AR3: Extra | AS3: Balance
A4: 1 | B4: =EDATE('My Debts'!$C$7,A4-1) -> 46327 | C4: 0 | D4: =(F4+J4+N4+R4+V4+Z4+AD4+AH4+AL4+AP4)-(I4+M4+Q4+U4+Y4+AC4+AG4+AK4+AO4+AS4) -> 530 | E4: =I4+M4+Q4+U4+Y4+AC4+AG4+AK4+AO4+AS4 -> 13184.04 | F4: =ROUND(Sorted!$E$2*(1+Sorted!$H$2),2) -> 908.63 | G4: =MIN(F4,Sorted!$G$2) -> 60 | H4: 0 | I4: =ROUND(F4-G4-H4,2) -> 848.63 | J4: =ROUND(Sorted!$E$3*(1+Sorted!$H$3),2) -> 1486.24 | K4: =MIN(J4,Sorted!$G$3) -> 55 | L4: 0 | M4: =ROUND(J4-K4-L4,2) -> 1431.24 | N4: =ROUND(Sorted!$E$4*(1+Sorted!$H$4),2) -> 4326.52 | O4: =MIN(N4,Sorted!$G$4) -> 240 | P4: 0 | Q4: =ROUND(N4-O4-P4,2) -> 4086.52 | R4: =ROUND(Sorted!$E$5*(1+Sorted!$H$5),2) -> 6992.65 | S4: =MIN(R4,Sorted!$G$5) -> 175 | T4: 0 | U4: =ROUND(R4-S4-T4,2) -> 6817.65 | V4: =ROUND(Sorted!$E$6*(1+Sorted!$H$6),2) -> 0 | W4: =MIN(V4,Sorted!$G$6) -> 0 | X4: 0 | Y4: =ROUND(V4-W4-X4,2) -> 0 | Z4: =ROUND(Sorted!$E$7*(1+Sorted!$H$7),2) -> 0 | AA4: =MIN(Z4,Sorted!$G$7) -> 0 | AB4: 0 | AC4: =ROUND(Z4-AA4-AB4,2) -> 0 | AD4: =ROUND(Sorted!$E$8*(1+Sorted!$H$8),2) -> 0 | AE4: =MIN(AD4,Sorted!$G$8) -> 0 | AF4: 0 | AG4: =ROUND(AD4-AE4-AF4,2) -> 0 | AH4: =ROUND(Sorted!$E$9*(1+Sorted!$H$9),2) -> 0 | AI4: =MIN(AH4,Sorted!$G$9) -> 0 | AJ4: 0 | AK4: =ROUND(AH4-AI4-AJ4,2) -> 0 | AL4: =ROUND(Sorted!$E$10*(1+Sorted!$H$10),2) -> 0 | AM4: =MIN(AL4,Sorted!$G$10) -> 0 | AN4: 0 | AO4: =ROUND(AL4-AM4-AN4,2) -> 0 | AP4: =ROUND(Sorted!$E$11*(1+Sorted!$H$11),2) -> 0 | AQ4: =MIN(AP4,Sorted!$G$11) -> 0 | AR4: 0 | AS4: =ROUND(AP4-AQ4-AR4,2) -> 0
A5: 2 | B5: =EDATE('My Debts'!$C$7,A5-1) -> 46357 | C5: 0 | D5: =(F5+J5+N5+R5+V5+Z5+AD5+AH5+AL5+AP5)-(I5+M5+Q5+U5+Y5+AC5+AG5+AK5+AO5+AS5) -> 530 | E5: =I5+M5+Q5+U5+Y5+AC5+AG5+AK5+AO5+AS5 -> 12865.12 | F5: =ROUND(I4*(1+Sorted!$H$2),2) -> 856.76 | G5: =MIN(F5,Sorted!$G$2) -> 60 | H5: 0 | I5: =ROUND(F5-G5-H5,2) -> 796.76 | J5: =ROUND(M4*(1+Sorted!$H$3),2) -> 1467.01 | K5: =MIN(J5,Sorted!$G$3) -> 55 | L5: 0 | M5: =ROUND(J5-K5-L5,2) -> 1412.01 | N5: =ROUND(Q4*(1+Sorted!$H$4),2) -> 4111.72 | O5: =MIN(N5,Sorted!$G$4) -> 240 | P5: 0 | Q5: =ROUND(N5-O5-P5,2) -> 3871.72 | R5: =ROUND(U4*(1+Sorted!$H$5),2) -> 6959.63 | S5: =MIN(R5,Sorted!$G$5) -> 175 | T5: 0 | U5: =ROUND(R5-S5-T5,2) -> 6784.63 | V5: =ROUND(Y4*(1+Sorted!$H$6),2) -> 0 | W5: =MIN(V5,Sorted!$G$6) -> 0 | X5: 0 | Y5: =ROUND(V5-W5-X5,2) -> 0 | Z5: =ROUND(AC4*(1+Sorted!$H$7),2) -> 0 | AA5: =MIN(Z5,Sorted!$G$7) -> 0 | AB5: 0 | AC5: =ROUND(Z5-AA5-AB5,2) -> 0 | AD5: =ROUND(AG4*(1+Sorted!$H$8),2) -> 0 | AE5: =MIN(AD5,Sorted!$G$8) -> 0 | AF5: 0 | AG5: =ROUND(AD5-AE5-AF5,2) -> 0 | AH5: =ROUND(AK4*(1+Sorted!$H$9),2) -> 0 | AI5: =MIN(AH5,Sorted!$G$9) -> 0 | AJ5: 0 | AK5: =ROUND(AH5-AI5-AJ5,2) -> 0 | AL5: =ROUND(AO4*(1+Sorted!$H$10),2) -> 0 | AM5: =MIN(AL5,Sorted!$G$10) -> 0 | AN5: 0 | AO5: =ROUND(AL5-AM5-AN5,2) -> 0 | AP5: =ROUND(AS4*(1+Sorted!$H$11),2) -> 0 | AQ5: =MIN(AP5,Sorted!$G$11) -> 0 | AR5: 0 | AS5: =ROUND(AP5-AQ5-AR5,2) -> 0
A6: 3 | B6: =EDATE('My Debts'!$C$7,A6-1) -> 46388 | C6: 0 | D6: =(F6+J6+N6+R6+V6+Z6+AD6+AH6+AL6+AP6)-(I6+M6+Q6+U6+Y6+AC6+AG6+AK6+AO6+AS6) -> 530 | E6: =I6+M6+Q6+U6+Y6+AC6+AG6+AK6+AO6+AS6 -> 12543.22 | F6: =ROUND(I5*(1+Sorted!$H$2),2) -> 804.4 | G6: =MIN(F6,Sorted!$G$2) -> 60 | H6: 0 | I6: =ROUND(F6-G6-H6,2) -> 744.4 | J6: =ROUND(M5*(1+Sorted!$H$3),2) -> 1447.3 | K6: =MIN(J6,Sorted!$G$3) -> 55 | L6: 0 | M6: =ROUND(J6-K6-L6,2) -> 1392.3 | N6: =ROUND(Q5*(1+Sorted!$H$4),2) -> 3895.6 | O6: =MIN(N6,Sorted!$G$4) -> 240 | P6: 0 | Q6: =ROUND(N6-O6-P6,2) -> 3655.6 | R6: =ROUND(U5*(1+Sorted!$H$5),2) -> 6925.92 | S6: =MIN(R6,Sorted!$G$5) -> 175 | T6: 0 | U6: =ROUND(R6-S6-T6,2) -> 6750.92 | V6: =ROUND(Y5*(1+Sorted!$H$6),2) -> 0 | W6: =MIN(V6,Sorted!$G$6) -> 0 | X6: 0 | Y6: =ROUND(V6-W6-X6,2) -> 0 | Z6: =ROUND(AC5*(1+Sorted!$H$7),2) -> 0 | AA6: =MIN(Z6,Sorted!$G$7) -> 0 | AB6: 0 | AC6: =ROUND(Z6-AA6-AB6,2) -> 0 | AD6: =ROUND(AG5*(1+Sorted!$H$8),2) -> 0 | AE6: =MIN(AD6,Sorted!$G$8) -> 0 | AF6: 0 | AG6: =ROUND(AD6-AE6-AF6,2) -> 0 | AH6: =ROUND(AK5*(1+Sorted!$H$9),2) -> 0 | AI6: =MIN(AH6,Sorted!$G$9) -> 0 | AJ6: 0 | AK6: =ROUND(AH6-AI6-AJ6,2) -> 0 | AL6: =ROUND(AO5*(1+Sorted!$H$10),2) -> 0 | AM6: =MIN(AL6,Sorted!$G$10) -> 0 | AN6: 0 | AO6: =ROUND(AL6-AM6-AN6,2) -> 0 | AP6: =ROUND(AS5*(1+Sorted!$H$11),2) -> 0 | AQ6: =MIN(AP6,Sorted!$G$11) -> 0 | AR6: 0 | AS6: =ROUND(AP6-AQ6-AR6,2) -> 0
A7: 4 | B7: =EDATE('My Debts'!$C$7,A7-1) -> 46419 | C7: 0 | D7: =(F7+J7+N7+R7+V7+Z7+AD7+AH7+AL7+AP7)-(I7+M7+Q7+U7+Y7+AC7+AG7+AK7+AO7+AS7) -> 530 | E7: =I7+M7+Q7+U7+Y7+AC7+AG7+AK7+AO7+AS7 -> 12218.28 | F7: =ROUND(I6*(1+Sorted!$H$2),2) -> 751.53 | G7: =MIN(F7,Sorted!$G$2) -> 60 | H7: 0 | I7: =ROUND(F7-G7-H7,2) -> 691.53 | J7: =ROUND(M6*(1+Sorted!$H$3),2) -> 1427.1 | K7: =MIN(J7,Sorted!$G$3) -> 55 | L7: 0 | M7: =ROUND(J7-K7-L7,2) -> 1372.1 | N7: =ROUND(Q6*(1+Sorted!$H$4),2) -> 3678.14 | O7: =MIN(N7,Sorted!$G$4) -> 240 | P7: 0 | Q7: =ROUND(N7-O7-P7,2) -> 3438.14 | R7: =ROUND(U6*(1+Sorted!$H$5),2) -> 6891.51 | S7: =MIN(R7,Sorted!$G$5) -> 175 | T7: 0 | U7: =ROUND(R7-S7-T7,2) -> 6716.51 | V7: =ROUND(Y6*(1+Sorted!$H$6),2) -> 0 | W7: =MIN(V7,Sorted!$G$6) -> 0 | X7: 0 | Y7: =ROUND(V7-W7-X7,2) -> 0 | Z7: =ROUND(AC6*(1+Sorted!$H$7),2) -> 0 | AA7: =MIN(Z7,Sorted!$G$7) -> 0 | AB7: 0 | AC7: =ROUND(Z7-AA7-AB7,2) -> 0 | AD7: =ROUND(AG6*(1+Sorted!$H$8),2) -> 0 | AE7: =MIN(AD7,Sorted!$G$8) -> 0 | AF7: 0 | AG7: =ROUND(AD7-AE7-AF7,2) -> 0 | AH7: =ROUND(AK6*(1+Sorted!$H$9),2) -> 0 | AI7: =MIN(AH7,Sorted!$G$9) -> 0 | AJ7: 0 | AK7: =ROUND(AH7-AI7-AJ7,2) -> 0 | AL7: =ROUND(AO6*(1+Sorted!$H$10),2) -> 0 | AM7: =MIN(AL7,Sorted!$G$10) -> 0 | AN7: 0 | AO7: =ROUND(AL7-AM7-AN7,2) -> 0 | AP7: =ROUND(AS6*(1+Sorted!$H$11),2) -> 0 | AQ7: =MIN(AP7,Sorted!$G$11) -> 0 | AR7: 0 | AS7: =ROUND(AP7-AQ7-AR7,2) -> 0
A8: 5 | B8: =EDATE('My Debts'!$C$7,A8-1) -> 46447 | C8: 0 | D8: =(F8+J8+N8+R8+V8+Z8+AD8+AH8+AL8+AP8)-(I8+M8+Q8+U8+Y8+AC8+AG8+AK8+AO8+AS8) -> 530 | E8: =I8+M8+Q8+U8+Y8+AC8+AG8+AK8+AO8+AS8 -> 11890.27 | F8: =ROUND(I7*(1+Sorted!$H$2),2) -> 698.16 | G8: =MIN(F8,Sorted!$G$2) -> 60 | H8: 0 | I8: =ROUND(F8-G8-H8,2) -> 638.16 | J8: =ROUND(M7*(1+Sorted!$H$3),2) -> 1406.39 | K8: =MIN(J8,Sorted!$G$3) -> 55 | L8: 0 | M8: =ROUND(J8-K8-L8,2) -> 1351.39 | N8: =ROUND(Q7*(1+Sorted!$H$4),2) -> 3459.34 | O8: =MIN(N8,Sorted!$G$4) -> 240 | P8: 0 | Q8: =ROUND(N8-O8-P8,2) -> 3219.34 | R8: =ROUND(U7*(1+Sorted!$H$5),2) -> 6856.38 | S8: =MIN(R8,Sorted!$G$5) -> 175 | T8: 0 | U8: =ROUND(R8-S8-T8,2) -> 6681.38 | V8: =ROUND(Y7*(1+Sorted!$H$6),2) -> 0 | W8: =MIN(V8,Sorted!$G$6) -> 0 | X8: 0 | Y8: =ROUND(V8-W8-X8,2) -> 0 | Z8: =ROUND(AC7*(1+Sorted!$H$7),2) -> 0 | AA8: =MIN(Z8,Sorted!$G$7) -> 0 | AB8: 0 | AC8: =ROUND(Z8-AA8-AB8,2) -> 0 | AD8: =ROUND(AG7*(1+Sorted!$H$8),2) -> 0 | AE8: =MIN(AD8,Sorted!$G$8) -> 0 | AF8: 0 | AG8: =ROUND(AD8-AE8-AF8,2) -> 0 | AH8: =ROUND(AK7*(1+Sorted!$H$9),2) -> 0 | AI8: =MIN(AH8,Sorted!$G$9) -> 0 | AJ8: 0 | AK8: =ROUND(AH8-AI8-AJ8,2) -> 0 | AL8: =ROUND(AO7*(1+Sorted!$H$10),2) -> 0 | AM8: =MIN(AL8,Sorted!$G$10) -> 0 | AN8: 0 | AO8: =ROUND(AL8-AM8-AN8,2) -> 0 | AP8: =ROUND(AS7*(1+Sorted!$H$11),2) -> 0 | AQ8: =MIN(AP8,Sorted!$G$11) -> 0 | AR8: 0 | AS8: =ROUND(AP8-AQ8-AR8,2) -> 0
A9: 6 | B9: =EDATE('My Debts'!$C$7,A9-1) -> 46478 | C9: 0 | D9: =(F9+J9+N9+R9+V9+Z9+AD9+AH9+AL9+AP9)-(I9+M9+Q9+U9+Y9+AC9+AG9+AK9+AO9+AS9) -> 530 | E9: =I9+M9+Q9+U9+Y9+AC9+AG9+AK9+AO9+AS9 -> 11559.15 | F9: =ROUND(I8*(1+Sorted!$H$2),2) -> 644.28 | G9: =MIN(F9,Sorted!$G$2) -> 60 | H9: 0 | I9: =ROUND(F9-G9-H9,2) -> 584.28 | J9: =ROUND(M8*(1+Sorted!$H$3),2) -> 1385.16 | K9: =MIN(J9,Sorted!$G$3) -> 55 | L9: 0 | M9: =ROUND(J9-K9-L9,2) -> 1330.16 | N9: =ROUND(Q8*(1+Sorted!$H$4),2) -> 3239.19 | O9: =MIN(N9,Sorted!$G$4) -> 240 | P9: 0 | Q9: =ROUND(N9-O9-P9,2) -> 2999.19 | R9: =ROUND(U8*(1+Sorted!$H$5),2) -> 6820.52 | S9: =MIN(R9,Sorted!$G$5) -> 175 | T9: 0 | U9: =ROUND(R9-S9-T9,2) -> 6645.52 | V9: =ROUND(Y8*(1+Sorted!$H$6),2) -> 0 | W9: =MIN(V9,Sorted!$G$6) -> 0 | X9: 0 | Y9: =ROUND(V9-W9-X9,2) -> 0 | Z9: =ROUND(AC8*(1+Sorted!$H$7),2) -> 0 | AA9: =MIN(Z9,Sorted!$G$7) -> 0 | AB9: 0 | AC9: =ROUND(Z9-AA9-AB9,2) -> 0 | AD9: =ROUND(AG8*(1+Sorted!$H$8),2) -> 0 | AE9: =MIN(AD9,Sorted!$G$8) -> 0 | AF9: 0 | AG9: =ROUND(AD9-AE9-AF9,2) -> 0 | AH9: =ROUND(AK8*(1+Sorted!$H$9),2) -> 0 | AI9: =MIN(AH9,Sorted!$G$9) -> 0 | AJ9: 0 | AK9: =ROUND(AH9-AI9-AJ9,2) -> 0 | AL9: =ROUND(AO8*(1+Sorted!$H$10),2) -> 0 | AM9: =MIN(AL9,Sorted!$G$10) -> 0 | AN9: 0 | AO9: =ROUND(AL9-AM9-AN9,2) -> 0 | AP9: =ROUND(AS8*(1+Sorted!$H$11),2) -> 0 | AQ9: =MIN(AP9,Sorted!$G$11) -> 0 | AR9: 0 | AS9: =ROUND(AP9-AQ9-AR9,2) -> 0
A10: 7 | B10: =EDATE('My Debts'!$C$7,A10-1) -> 46508 | C10: 0 | D10: =(F10+J10+N10+R10+V10+Z10+AD10+AH10+AL10+AP10)-(I10+M10+Q10+U10+Y10+AC10+AG10+AK10+AO10+AS10) -> 530 | E10: =I10+M10+Q10+U10+Y10+AC10+AG10+AK10+AO10+AS10 -> 11224.88 | F10: =ROUND(I9*(1+Sorted!$H$2),2) -> 589.88 | G10: =MIN(F10,Sorted!$G$2) -> 60 | H10: 0 | I10: =ROUND(F10-G10-H10,2) -> 529.88 | J10: =ROUND(M9*(1+Sorted!$H$3),2) -> 1363.4 | K10: =MIN(J10,Sorted!$G$3) -> 55 | L10: 0 | M10: =ROUND(J10-K10-L10,2) -> 1308.4 | N10: =ROUND(Q9*(1+Sorted!$H$4),2) -> 3017.69 | O10: =MIN(N10,Sorted!$G$4) -> 240 | P10: 0 | Q10: =ROUND(N10-O10-P10,2) -> 2777.69 | R10: =ROUND(U9*(1+Sorted!$H$5),2) -> 6783.91 | S10: =MIN(R10,Sorted!$G$5) -> 175 | T10: 0 | U10: =ROUND(R10-S10-T10,2) -> 6608.91 | V10: =ROUND(Y9*(1+Sorted!$H$6),2) -> 0 | W10: =MIN(V10,Sorted!$G$6) -> 0 | X10: 0 | Y10: =ROUND(V10-W10-X10,2) -> 0 | Z10: =ROUND(AC9*(1+Sorted!$H$7),2) -> 0 | AA10: =MIN(Z10,Sorted!$G$7) -> 0 | AB10: 0 | AC10: =ROUND(Z10-AA10-AB10,2) -> 0 | AD10: =ROUND(AG9*(1+Sorted!$H$8),2) -> 0 | AE10: =MIN(AD10,Sorted!$G$8) -> 0 | AF10: 0 | AG10: =ROUND(AD10-AE10-AF10,2) -> 0 | AH10: =ROUND(AK9*(1+Sorted!$H$9),2) -> 0 | AI10: =MIN(AH10,Sorted!$G$9) -> 0 | AJ10: 0 | AK10: =ROUND(AH10-AI10-AJ10,2) -> 0 | AL10: =ROUND(AO9*(1+Sorted!$H$10),2) -> 0 | AM10: =MIN(AL10,Sorted!$G$10) -> 0 | AN10: 0 | AO10: =ROUND(AL10-AM10-AN10,2) -> 0 | AP10: =ROUND(AS9*(1+Sorted!$H$11),2) -> 0 | AQ10: =MIN(AP10,Sorted!$G$11) -> 0 | AR10: 0 | AS10: =ROUND(AP10-AQ10-AR10,2) -> 0
A11: 8 | B11: =EDATE('My Debts'!$C$7,A11-1) -> 46539 | C11: 0 | D11: =(F11+J11+N11+R11+V11+Z11+AD11+AH11+AL11+AP11)-(I11+M11+Q11+U11+Y11+AC11+AG11+AK11+AO11+AS11) -> 530 | E11: =I11+M11+Q11+U11+Y11+AC11+AG11+AK11+AO11+AS11 -> 10887.42 | F11: =ROUND(I10*(1+Sorted!$H$2),2) -> 534.96 | G11: =MIN(F11,Sorted!$G$2) -> 60 | H11: 0 | I11: =ROUND(F11-G11-H11,2) -> 474.96 | J11: =ROUND(M10*(1+Sorted!$H$3),2) -> 1341.1 | K11: =MIN(J11,Sorted!$G$3) -> 55 | L11: 0 | M11: =ROUND(J11-K11-L11,2) -> 1286.1 | N11: =ROUND(Q10*(1+Sorted!$H$4),2) -> 2794.82 | O11: =MIN(N11,Sorted!$G$4) -> 240 | P11: 0 | Q11: =ROUND(N11-O11-P11,2) -> 2554.82 | R11: =ROUND(U10*(1+Sorted!$H$5),2) -> 6746.54 | S11: =MIN(R11,Sorted!$G$5) -> 175 | T11: 0 | U11: =ROUND(R11-S11-T11,2) -> 6571.54 | V11: =ROUND(Y10*(1+Sorted!$H$6),2) -> 0 | W11: =MIN(V11,Sorted!$G$6) -> 0 | X11: 0 | Y11: =ROUND(V11-W11-X11,2) -> 0 | Z11: =ROUND(AC10*(1+Sorted!$H$7),2) -> 0 | AA11: =MIN(Z11,Sorted!$G$7) -> 0 | AB11: 0 | AC11: =ROUND(Z11-AA11-AB11,2) -> 0 | AD11: =ROUND(AG10*(1+Sorted!$H$8),2) -> 0 | AE11: =MIN(AD11,Sorted!$G$8) -> 0 | AF11: 0 | AG11: =ROUND(AD11-AE11-AF11,2) -> 0 | AH11: =ROUND(AK10*(1+Sorted!$H$9),2) -> 0 | AI11: =MIN(AH11,Sorted!$G$9) -> 0 | AJ11: 0 | AK11: =ROUND(AH11-AI11-AJ11,2) -> 0 | AL11: =ROUND(AO10*(1+Sorted!$H$10),2) -> 0 | AM11: =MIN(AL11,Sorted!$G$10) -> 0 | AN11: 0 | AO11: =ROUND(AL11-AM11-AN11,2) -> 0 | AP11: =ROUND(AS10*(1+Sorted!$H$11),2) -> 0 | AQ11: =MIN(AP11,Sorted!$G$11) -> 0 | AR11: 0 | AS11: =ROUND(AP11-AQ11-AR11,2) -> 0
A12: 9 | B12: =EDATE('My Debts'!$C$7,A12-1) -> 46569 | C12: 0 | D12: =(F12+J12+N12+R12+V12+Z12+AD12+AH12+AL12+AP12)-(I12+M12+Q12+U12+Y12+AC12+AG12+AK12+AO12+AS12) -> 530 | E12: =I12+M12+Q12+U12+Y12+AC12+AG12+AK12+AO12+AS12 -> 10546.71 | F12: =ROUND(I11*(1+Sorted!$H$2),2) -> 479.51 | G12: =MIN(F12,Sorted!$G$2) -> 60 | H12: 0 | I12: =ROUND(F12-G12-H12,2) -> 419.51 | J12: =ROUND(M11*(1+Sorted!$H$3),2) -> 1318.24 | K12: =MIN(J12,Sorted!$G$3) -> 55 | L12: 0 | M12: =ROUND(J12-K12-L12,2) -> 1263.24 | N12: =ROUND(Q11*(1+Sorted!$H$4),2) -> 2570.57 | O12: =MIN(N12,Sorted!$G$4) -> 240 | P12: 0 | Q12: =ROUND(N12-O12-P12,2) -> 2330.57 | R12: =ROUND(U11*(1+Sorted!$H$5),2) -> 6708.39 | S12: =MIN(R12,Sorted!$G$5) -> 175 | T12: 0 | U12: =ROUND(R12-S12-T12,2) -> 6533.39 | V12: =ROUND(Y11*(1+Sorted!$H$6),2) -> 0 | W12: =MIN(V12,Sorted!$G$6) -> 0 | X12: 0 | Y12: =ROUND(V12-W12-X12,2) -> 0 | Z12: =ROUND(AC11*(1+Sorted!$H$7),2) -> 0 | AA12: =MIN(Z12,Sorted!$G$7) -> 0 | AB12: 0 | AC12: =ROUND(Z12-AA12-AB12,2) -> 0 | AD12: =ROUND(AG11*(1+Sorted!$H$8),2) -> 0 | AE12: =MIN(AD12,Sorted!$G$8) -> 0 | AF12: 0 | AG12: =ROUND(AD12-AE12-AF12,2) -> 0 | AH12: =ROUND(AK11*(1+Sorted!$H$9),2) -> 0 | AI12: =MIN(AH12,Sorted!$G$9) -> 0 | AJ12: 0 | AK12: =ROUND(AH12-AI12-AJ12,2) -> 0 | AL12: =ROUND(AO11*(1+Sorted!$H$10),2) -> 0 | AM12: =MIN(AL12,Sorted!$G$10) -> 0 | AN12: 0 | AO12: =ROUND(AL12-AM12-AN12,2) -> 0 | AP12: =ROUND(AS11*(1+Sorted!$H$11),2) -> 0 | AQ12: =MIN(AP12,Sorted!$G$11) -> 0 | AR12: 0 | AS12: =ROUND(AP12-AQ12-AR12,2) -> 0
A13: 10 | B13: =EDATE('My Debts'!$C$7,A13-1) -> 46600 | C13: 0 | D13: =(F13+J13+N13+R13+V13+Z13+AD13+AH13+AL13+AP13)-(I13+M13+Q13+U13+Y13+AC13+AG13+AK13+AO13+AS13) -> 530 | E13: =I13+M13+Q13+U13+Y13+AC13+AG13+AK13+AO13+AS13 -> 10202.73 | F13: =ROUND(I12*(1+Sorted!$H$2),2) -> 423.53 | G13: =MIN(F13,Sorted!$G$2) -> 60 | H13: 0 | I13: =ROUND(F13-G13-H13,2) -> 363.53 | J13: =ROUND(M12*(1+Sorted!$H$3),2) -> 1294.81 | K13: =MIN(J13,Sorted!$G$3) -> 55 | L13: 0 | M13: =ROUND(J13-K13-L13,2) -> 1239.81 | N13: =ROUND(Q12*(1+Sorted!$H$4),2) -> 2344.94 | O13: =MIN(N13,Sorted!$G$4) -> 240 | P13: 0 | Q13: =ROUND(N13-O13-P13,2) -> 2104.94 | R13: =ROUND(U12*(1+Sorted!$H$5),2) -> 6669.45 | S13: =MIN(R13,Sorted!$G$5) -> 175 | T13: 0 | U13: =ROUND(R13-S13-T13,2) -> 6494.45 | V13: =ROUND(Y12*(1+Sorted!$H$6),2) -> 0 | W13: =MIN(V13,Sorted!$G$6) -> 0 | X13: 0 | Y13: =ROUND(V13-W13-X13,2) -> 0 | Z13: =ROUND(AC12*(1+Sorted!$H$7),2) -> 0 | AA13: =MIN(Z13,Sorted!$G$7) -> 0 | AB13: 0 | AC13: =ROUND(Z13-AA13-AB13,2) -> 0 | AD13: =ROUND(AG12*(1+Sorted!$H$8),2) -> 0 | AE13: =MIN(AD13,Sorted!$G$8) -> 0 | AF13: 0 | AG13: =ROUND(AD13-AE13-AF13,2) -> 0 | AH13: =ROUND(AK12*(1+Sorted!$H$9),2) -> 0 | AI13: =MIN(AH13,Sorted!$G$9) -> 0 | AJ13: 0 | AK13: =ROUND(AH13-AI13-AJ13,2) -> 0 | AL13: =ROUND(AO12*(1+Sorted!$H$10),2) -> 0 | AM13: =MIN(AL13,Sorted!$G$10) -> 0 | AN13: 0 | AO13: =ROUND(AL13-AM13-AN13,2) -> 0 | AP13: =ROUND(AS12*(1+Sorted!$H$11),2) -> 0 | AQ13: =MIN(AP13,Sorted!$G$11) -> 0 | AR13: 0 | AS13: =ROUND(AP13-AQ13-AR13,2) -> 0
